Workbook

Sheet 1
A1: Injection molding machine number | B1: Type of cap | C1: Type of cap | D1: Color of the cap | E1: Cap code | F1: номер партии | G1: Planned production, pcs | H1: Actual production, pcs | I1: Target cycle time, seconds | J1: Target weight of cap, grams. | K1: Number of cavities in the mold | L1: Target productivity per minute, pcs. | M1: Time for transition (including replacement of the mold), min. | N1: Time for daily maintenance of the mold, min | O1: Other stops not dependent on operating personnel, min | P1: Description of the reason for stopping column "N", "L" | Q1: Total batch production time, min | R1: Defective raw materials, kg | S1: Percentage of defective materials | T1: ОЕЕ1 | U1: ОЕЕ2 | V1: ОЕЕ | X1: Код простоя, TDE. | Y1: Прочие остановки, мин. | Z1: Код простоя, TDE. | AA1: Прочие остановки, мин. | AB1: Описание причины остановки столбик "R; T" | AC1: Время на ежесменное техническое обслуживание пресс-формы, мин.
A2: 1 | B2: с52г/2 | C2: =VLOOKUP(B2,Setup!A:B,2,) -> Glossy Spray Cap, Vertical Spray, 52mm, Shape #2 | D2: orange | E2: СР310 | G2: 30150 | H2: 30150 | I2: 11.3 | J2: 6.7 | K2: 8 | L2: =(60/I2)*K2 -> 42.477876 | M2: 30 | N2: 15 | O2: 375 | P2: troubleshooting an injection molding machine | Q2: =765+30+375 -> 1170 | R2: =6.2+5.1 -> 11.3 | S2: =R2/(G2*J2/1000) -> 0.055939209 | T2: =(H2/(L2*(Q2-N2-M2-O2)))*((Q2-N2-M2-O2)/(Q2-N2-O2)) -> 0.90997596 | U2: =(H2*J2/(H2*J2+R2*1000)) -> 0.94702421 | V2: =T2*U2 -> 0.86176927 | X2: 001 | Y2: 30 | Z2: 016 | AA2: 375 | AB2: Запуск после ТО,Сбой в работе ТПА | AC2: 15
B3: с52г/2 | C3: =VLOOKUP(B3,Setup!A:B,2,) -> Glossy Spray Cap, Vertical Spray, 52mm, Shape #2 | D3: pink | E3: СР303 | G3: 100350 | H3: 100350 | I3: 11.3 | J3: 6.7 | K3: 8 | L3: =(60/I3)*K3 -> 42.477876 | M3: 10 | N3: =15+15+15 -> 45 | Q3: =70+720+720+720+200 -> 2430 | R3: =2.3+1.1+5.1+2.5+8.8 -> 19.8 | S3: =R3/(G3*J3/1000) -> 0.029449167 | T3: =(H3/(L3*(Q3-N3-M3-O3)))*((Q3-N3-M3-O3)/(Q3-N3-O3)) -> 0.99052673 | U3: =(H3*J3/(H3*J3+R3*1000)) -> 0.97139328 | V3: =T3*U3 -> 0.96219101 | AC3: =15+15+20 -> 50
B4: с52г/2 | C4: =VLOOKUP(B4,Setup!A:B,2,) -> Glossy Spray Cap, Vertical Spray, 52mm, Shape #2 | D4: coral | E4: СР308 | G4: 17100 | H4: 17100 | I4: 11.3 | J4: 6.7 | K4: 8 | L4: =(60/I4)*K4 -> 42.477876 | M4: 30 | Q4: 445 | R4: 5.1 | S4: =R4/(G4*J4/1000) -> 0.044514271 | T4: =(H4/(L4*(Q4-N4-M4-O4)))*((Q4-N4-M4-O4)/(Q4-N4-O4)) -> 0.90463483 | U4: =(H4*J4/(H4*J4+R4*1000)) -> 0.9573828 | V4: =T4*U4 -> 0.86608183
B5: с52г/2 | C5: =VLOOKUP(B5,Setup!A:B,2,) -> Glossy Spray Cap, Vertical Spray, 52mm, Shape #2 | D5: light blue | E5: СР306 | G5: 50400 | H5: 50400 | I5: 11.3 | J5: 6.7 | K5: 8 | L5: =(60/I5)*K5 -> 42.477876 | M5: 20 | N5: =15+15 -> 30 | Q5: =75+720+515 -> 1310 | R5: =1.6+1+4.3 -> 6.9 | S5: =R5/(G5*J5/1000) -> 0.020433547 | T5: =(H5/(L5*(Q5-N5-M5-O5)))*((Q5-N5-M5-O5)/(Q5-N5-O5)) -> 0.92695313 | U5: =(H5*J5/(H5*J5+R5*1000)) -> 0.97997562 | V5: =T5*U5 -> 0.90839147 | AC5: =25+15 -> 40
B6: с52г/2 | C6: =VLOOKUP(B6,Setup!A:B,2,) -> Glossy Spray Cap, Vertical Spray, 52mm, Shape #2 | D6: blue | E6: СР314 | G6: 10350 | H6: 10350 | I6: 11.3 | J6: 6.7 | K6: 8 | L6: =(60/I6)*K6 -> 42.477876 | M6: 20 | Q6: =205+80 -> 285 | R6: =6.4+1.4 -> 7.8 | S6: =R6/(G6*J6/1000) -> 0.11248107 | T6: =(H6/(L6*(Q6-N6-M6-O6)))*((Q6-N6-M6-O6)/(Q6-N6-O6)) -> 0.85493421 | U6: =(H6*J6/(H6*J6+R6*1000)) -> 0.8988917 | V6: =T6*U6 -> 0.76849326
B7: з35м/дм | C7: =VLOOKUP(B7,Setup!A:B,2,) -> Matte Protective Cap - Component of 35mm Hair Styling Mousse Dispenser | D7: black | E7: СР534/2 | G7: 100500 | H7: 100500 | I7: 9.65 | J7: 3 | K7: 12 | L7: =(60/I7)*K7 -> 74.611399 | M7: =20+130 -> 150 | N7: =15+15 -> 30 | P7: replacement of the mold | Q7: =370+720+480+130 -> 1700 | R7: =0.4+0.5+0.8 -> 1.7 | S7: =R7/(G7*J7/1000) -> 0.0056384743 | T7: =(H7/(L7*(Q7-N7-M7-O7)))*((Q7-N7-M7-O7)/(Q7-N7-O7)) -> 0.80657435 | U7: =(H7*J7/(H7*J7+R7*1000)) -> 0.99439314 | V7: =T7*U7 -> 0.802052 | X7: 005 | Y7: 130 | AB7: Замена ПФ | AC7: =15+10 -> 25
B8: с52г/2 | C8: =VLOOKUP(B8,Setup!A:B,2,) -> Glossy Spray Cap, Vertical Spray, 52mm, Shape #2 | D8: navy Waves | E8: СР309 | G8: 21150 | H8: 21150 | I8: 11.3 | J8: 6.7 | K8: 8 | L8: =(60/I8)*K8 -> 42.477876 | M8: 160 | N8: =15+15 -> 30 | P8: replacement of the mold | Q8: =240+160+295 -> 695 | R8: =8.3+3.3 -> 11.6 | S8: =R8/(G8*J8/1000) -> 0.081860203 | T8: =(H8/(L8*(Q8-N8-M8-O8)))*((Q8-N8-M8-O8)/(Q8-N8-O8)) -> 0.7487312 | U8: =(H8*J8/(H8*J8+R8*1000)) -> 0.92433384 | V8: =T8*U8 -> 0.69207759 | X8: 005 | Y8: 160 | AB8: замена ПФ | AC8: =20+15 -> 35
B9: с52г/2 | C9: =VLOOKUP(B9,Setup!A:B,2,) -> Glossy Spray Cap, Vertical Spray, 52mm, Shape #2 | D9: Turquoise | E9: СР307 | G9: =46350+900 -> 47250 | H9: =46350+900 -> 47250 | I9: 11.3 | J9: 6.7 | K9: 8 | L9: =(60/I9)*K9 -> 42.477876 | M9: 20 | N9: =15 -> 15 | Q9: =425+720+20 -> 1165 | R9: =5.7+1.8+0.2 -> 7.7 | S9: =R9/(G9*J9/1000) -> 0.02432283 | T9: =(H9/(L9*(Q9-N9-M9-O9)))*((Q9-N9-M9-O9)/(Q9-N9-O9)) -> 0.96725543 | U9: =(H9*J9/(H9*J9+R9*1000)) -> 0.97625472 | V9: =T9*U9 -> 0.94428769 | AC9: =15 -> 15
B10: с52г/2 | C10: =VLOOKUP(B10,Setup!A:B,2,) -> Glossy Spray Cap, Vertical Spray, 52mm, Shape #2 | D10: Turquoise | E10: СР351 | G10: 25200 | H10: 25200 | I10: 11.3 | J10: 6.7 | K10: 8 | L10: =(60/I10)*K10 -> 42.477876 | M10: 15 | N10: 15 | Q10: 660 | R10: 3.6 | S10: =R10/(G10*J10/1000) -> 0.021321962 | T10: =(H10/(L10*(Q10-N10-M10-O10)))*((Q10-N10-M10-O10)/(Q10-N10-O10)) -> 0.91976744 | U10: =(H10*J10/(H10*J10+R10*1000)) -> 0.97912317 | V10: =T10*U10 -> 0.90056562 | AC10: 15
B11: с52г/2 | C11: =VLOOKUP(B11,Setup!A:B,2,) -> Glossy Spray Cap, Vertical Spray, 52mm, Shape #2 | D11: Orange | E11: СР310 | G11: 70200 | H11: 70200 | I11: 11.3 | J11: 6.7 | K11: 8 | L11: =(60/I11)*K11 -> 42.477876 | M11: 15 | N11: =15+15+15 -> 45 | Q11: =30+720+720+315 -> 1785 | R11: =4.2+2.2+1.1+3.5 -> 11 | S11: =R11/(G11*J11/1000) -> 0.023387337 | T11: =(H11/(L11*(Q11-N11-M11-O11)))*((Q11-N11-M11-O11)/(Q11-N11-O11)) -> 0.94978448 | U11: =(H11*J11/(H11*J11+R11*1000)) -> 0.97714713 | V11: =T11*U11 -> 0.92807918 | AC11: =15+15+15 -> 45
B12: с52г/2 | C12: =VLOOKUP(B12,Setup!A:B,2,) -> Glossy Spray Cap, Vertical Spray, 52mm, Shape #2 | D12: Pink | E12: СР303 | G12: =298800+31500 -> 330300 | H12: =298800+31500 -> 330300 | I12: 11.3 | J12: 6.7 | K12: 8 | L12: =(60/I12)*K12 -> 42.477876 | M12: =15 -> 15 | N12: =15+15+15+15+15+15+15+15+15+15+15+15 -> 180 | Q12: =405+720+720+720+720+720+720+720+720+720+720+85 -> 7690 | R12: =4.6+0.7+1.5+0.9+0.8+4.5+0.6+1.3+1.2+1.1+0.6+1.6 -> 19.4 | S12: =R12/(G12*J12/1000) -> 0.0087663409 | T12: =(H12/(L12*(Q12-N12-M12-O12)))*((Q12-N12-M12-O12)/(Q12-N12-O12)) -> 1.0353945 | U12: =(H12*J12/(H12*J12+R12*1000)) -> 0.99130984 | V12: =T12*U12 -> 1.0263967 | AC12: =15+20+25+15+25+10+15+45+25+15+10+15 -> 235
B13: с52г/2 | C13: =VLOOKUP(B13,Setup!A:B,2,) -> Glossy Spray Cap, Vertical Spray, 52mm, Shape #2 | D13: Crimson | E13: СР304 | G13: 40050 | H13: 40050 | I13: 11.3 | J13: 6.7 | K13: 8 | L13: =(60/I13)*K13 -> 42.477876 | M13: 35 | N13: 15 | Q13: =635+400 -> 1035 | R13: =6+0.9 -> 6.9 | S13: =R13/(G13*J13/1000) -> 0.025714126 | T13: =(H13/(L13*(Q13-N13-M13-O13)))*((Q13-N13-M13-O13)/(Q13-N13-O13)) -> 0.92435662 | U13: =(H13*J13/(H13*J13+R13*1000)) -> 0.97493051 | V13: =T13*U13 -> 0.90118347 | AC13: 15
B14: с52г/2 | C14: =VLOOKUP(B14,Setup!A:B,2,) -> Glossy Spray Cap, Vertical Spray, 52mm, Shape #2 | D14: Orange | E14: СР310 | G14: 100350 | H14: 100350 | I14: 11.3 | J14: 6.7 | K14: 8 | L14: =(60/I14)*K14 -> 42.477876 | M14: 25 | N14: =15+15+15 -> 45 | Q14: =320+720+720+720+40 -> 2520 | R14: =5.3+0.9+1.1+2 -> 9.3 | S14: =R14/(G14*J14/1000) -> 0.013832184 | T14: =(H14/(L14*(Q14-N14-M14-O14)))*((Q14-N14-M14-O14)/(Q14-N14-O14)) -> 0.95450758 | U14: =(H14*J14/(H14*J14+R14*1000)) -> 0.98635653 | V14: =T14*U14 -> 0.94148478 | AC14: =15+15+10 -> 40
B15: з45м | C15: =VLOOKUP(B15,Setup!A:B,2,) -> Matte Protective Cap, 45mm | D15: Red | E15: СР440 | G15: =327000+23400 -> 350400 | H15: =327000+23400 -> 350400 | I15: 7.5 | J15: 5 | K15: 8 | L15: =(60/I15)*K15 -> 64 | M15: =20+100 -> 120 | N15: =15+15+15+15+15+15+15+15 -> 120 | P15: replacement of the mold | Q15: =330+100+720+720+720+720+720+720+720+360 -> 5830 | R15: =1.3+3.1+0.6+0.5+0.7+0.4+1+0.4 -> 8 | S15: =R15/(G15*J15/1000) -> 0.00456621 | T15: =(H15/(L15*(Q15-N15-M15-O15)))*((Q15-N15-M15-O15)/(Q15-N15-O15)) -> 0.95884413 | U15: =(H15*J15/(H15*J15+R15*1000)) -> 0.99545455 | V15: =T15*U15 -> 0.95448575 | X15: 005 | Y15: 100 | AB15: замена ПФ | AC15: =10+10+10+15+10+10+10+10 -> 85
B16: з52м | C16: =VLOOKUP(B16,Setup!A:B,2,) -> Matte Protective Cap, 52mm | D16: Black | E16: СР408 | G16: 320400 | H16: 320400 | I16: 7.3 | J16: 6.1 | K16: 8 | L16: =(60/I16)*K16 -> 65.753425 | M16: =50+100 -> 150 | N16: =15+15+15+15+15+15+15+15 -> 120 | P16: replacement of the mold | Q16: =230+720+720+720+720+720+720+720+70+100 -> 5440 | R16: =10.5+5.2+1.3+3.2+1.5+0.5+1.4+7.7+1.7 -> 33 | S16: =R16/(G16*J16/1000) -> 0.016884632 | T16: =(H16/(L16*(Q16-N16-M16-O16)))*((Q16-N16-M16-O16)/(Q16-N16-O16)) -> 0.91593045 | U16: =(H16*J16/(H16*J16+R16*1000)) -> 0.98339573 | V16: =T16*U16 -> 0.90072209 | X16: 005 | Y16: 100 | AB16: замена ПФ | AC16: =40+10+25+10+10+10+35+10 -> 150
B17: з52м | C17: =VLOOKUP(B17,Setup!A:B,2,) -> Matte Protective Cap, 52mm | D17: Red | E17: СР471 | G17: 67500 | H17: 67500 | I17: 7.3 | J17: 6.1 | K17: 8 | L17: =(60/I17)*K17 -> 65.753425 | M17: 25 | N17: 15 | Q17: =630+440 -> 1070 | R17: =7+2.8 -> 9.8 | S17: =R17/(G17*J17/1000) -> 0.02380085 | T17: =(H17/(L17*(Q17-N17-M17-O17)))*((Q17-N17-M17-O17)/(Q17-N17-O17)) -> 0.97304502 | U17: =(H17*J17/(H17*J17+R17*1000)) -> 0.97675246 | V17: =T17*U17 -> 0.95042412 | AC17: 20
B18: з52м | C18: =VLOOKUP(B18,Setup!A:B,2,) -> Matte Protective Cap, 52mm | D18: Silver | E18: СР521 | G18: 40050 | H18: 40050 | I18: 7.3 | J18: 6.1 | K18: 8 | L18: =(60/I18)*K18 -> 65.753425 | M18: 20 | N18: 15 | Q18: =280+390 -> 670 | R18: =7.2+1.4 -> 8.6 | S18: =R18/(G18*J18/1000) -> 0.035201899 | T18: =(H18/(L18*(Q18-N18-M18-O18)))*((Q18-N18-M18-O18)/(Q18-N18-O18)) -> 0.92991412 | U18: =(H18*J18/(H18*J18+R18*1000)) -> 0.96599514 | V18: =T18*U18 -> 0.89829252 | AC18: 15
B19: з52м | C19: =VLOOKUP(B19,Setup!A:B,2,) -> Matte Protective Cap, 52mm | D19: Black | E19: СР096 | G19: 150300 | H19: 150300 | I19: 7.3 | J19: 6.1 | K19: 8 | L19: =(60/I19)*K19 -> 65.753425 | M19: 30 | N19: =15+15+15 -> 45 | Q19: =330+720+720+720 -> 2490 | R19: =7.6+1.2+1.1+1.6 -> 11.5 | S19: =R19/(G19*J19/1000) -> 0.01254322 | T19: =(H19/(L19*(Q19-N19-M19-O19)))*((Q19-N19-M19-O19)/(Q19-N19-O19)) -> 0.93489264 | U19: =(H19*J19/(H19*J19+R19*1000)) -> 0.98761216 | V19: =T19*U19 -> 0.92331134 | AC19: =10+15+10 -> 35
G20: =SUM(G2:G19) -> 1872000 | H20: =SUM(H2:H19) -> 1872000 | M20: =SUM(M2:M19) -> 890 | N20: =SUM(N2:N19) -> 780 | O20: =SUM(O2:O19) -> 375 | Q20: =SUM(Q2:Q19) -> 38390 | R20: =SUM(R2:R19) -> 193

Sheet 2
A1: Injection molding machine number | B1: Type of cap | C1: Type of cap | D1: Color of the cap | E1: Cap code | F1: номер партии | G1: Planned production, pcs | H1: Actual production, pcs | I1: Target cycle time, seconds | J1: Target weight of cap, grams. | K1: Number of cavities in the mold | L1: Target productivity per minute, pcs. | M1: Time for transition (including replacement of the mold), min. | N1: Time for daily maintenance of the mold, min | O1: Other stops not dependent on operating personnel, min | P1: Description of the reason for stopping column "N", "L" | Q1: Total batch production time, min | R1: Defective raw materials, kg | S1: Percentage of defective materials | T1: ОЕЕ1 | U1: ОЕЕ2 | V1: ОЕЕ | X1: Код простоя, TDE. | Y1: Прочие остановки, мин. | Z1: Код простоя, TDE. | AA1: Прочие остановки, мин. | AB1: Описание причины остановки столбик "R; T" | AC1: Время на ежесменное техническое обслуживание пресс-формы, мин.
A2: 2 | B2: с52г/1 | C2: =VLOOKUP(B2,Setup!A:B,2,) -> Glossy Spray Cap, Vertical Spray, 52mm, Shape #1 | D2: Violet | E2: СР477 | G2: 60300 | H2: 60300 | I2: 11.3 | J2: 8.2 | K2: 8 | L2: =(60/I2)*K2 -> 42.477876 | M2: 30 | N2: =15+15 -> 30 | Q2: =720+720+125+30 -> 1595 | R2: =7.7+2.7+0.8+1 -> 12.2 | S2: =R2/(G2*J2/1000) -> 0.024673381 | T2: =(H2/(L2*(Q2-N2-M2-O2)))*((Q2-N2-M2-O2)/(Q2-N2-O2)) -> 0.90706869 | U2: =(H2*J2/(H2*J2+R2*1000)) -> 0.97592074 | V2: =T2*U2 -> 0.88522714 | X2: 001 | Y2: 30 | AC2: =10+10 -> 20
B3: с52г/1 | C3: =VLOOKUP(B3,Setup!A:B,2,) -> Glossy Spray Cap, Vertical Spray, 52mm, Shape #1 | D3: Blue | E3: СР479 | G3: 20250 | H3: 20250 | I3: 11.3 | J3: 8.2 | K3: 8 | L3: =(60/I3)*K3 -> 42.477876 | M3: 20 | Q3: 525 | R3: 6 | S3: =R3/(G3*J3/1000) -> 0.036133695 | T3: =(H3/(L3*(Q3-N3-M3-O3)))*((Q3-N3-M3-O3)/(Q3-N3-O3)) -> 0.90803571 | U3: =(H3*J3/(H3*J3+R3*1000)) -> 0.96512642 | V3: =T3*U3 -> 0.87636926
B4: с52г/1 | C4: =VLOOKUP(B4,Setup!A:B,2,) -> Glossy Spray Cap, Vertical Spray, 52mm, Shape #1 | D4: Misty Blue | E4: СР399 | G4: 25200 | H4: 25200 | I4: 11.3 | J4: 8.2 | K4: 8 | L4: =(60/I4)*K4 -> 42.477876 | M4: 10 | N4: 15 | Q4: =70+600 -> 670 | R4: =0.8+2 -> 2.8 | S4: =R4/(G4*J4/1000) -> 0.013550136 | T4: =(H4/(L4*(Q4-N4-M4-O4)))*((Q4-N4-M4-O4)/(Q4-N4-O4)) -> 0.90572519 | U4: =(H4*J4/(H4*J4+R4*1000)) -> 0.98663102 | V4: =T4*U4 -> 0.89361657 | X4: 006 | Y4: 120 | AB4: Снятие ПФ | AC4: 15
B5: с52г/1 | C5: =VLOOKUP(B5,Setup!A:B,2,) -> Glossy Spray Cap, Vertical Spray, 52mm, Shape #1 | D5: Ultramarine | E5: СР422 | G5: 130050 | H5: 130050 | I5: 11.3 | J5: 8.2 | K5: 8 | L5: =(60/I5)*K5 -> 42.477876 | M5: 120 | N5: =15+15+15+15+15 -> 75 | O5: 535 | P5: major mold maintenance | Q5: =185+720+720+720+720+145+120+535 -> 3865 | R5: =3.5+1.7+1.2+1.1+0.9+1.9 -> 10.3 | S5: =R5/(G5*J5/1000) -> 0.0096585741 | T5: =(H5/(L5*(Q5-N5-M5-O5)))*((Q5-N5-M5-O5)/(Q5-N5-O5)) -> 0.9405818 | U5: =(H5*J5/(H5*J5+R5*1000)) -> 0.99043382 | V5: =T5*U5 -> 0.93158402 | X5: 001 | Y5: 535 | AB5: Обслуживание ПФ | AC5: =10+25+10+10+25 -> 80
B6: с52г/1 | C6: =VLOOKUP(B6,Setup!A:B,2,) -> Glossy Spray Cap, Vertical Spray, 52mm, Shape #1 | D6: Pale Blue | E6: СР492 | G6: =136350+4050 -> 140400 | H6: =136350+4050 -> 140400 | I6: 11.3 | J6: 8.2 | K6: 8 | L6: =(60/I6)*K6 -> 42.477876 | M6: 45 | N6: =15+15+15+15 -> 60 | Q6: =575+720+720+720+720+110 -> 3565 | R6: =9+1.3+2.9+1+1.2+3.7 -> 19.1 | S6: =R6/(G6*J6/1000) -> 0.01659023 | T6: =(H6/(L6*(Q6-N6-M6-O6)))*((Q6-N6-M6-O6)/(Q6-N6-O6)) -> 0.94300999 | U6: =(H6*J6/(H6*J6+R6*1000)) -> 0.98368051 | V6: =T6*U6 -> 0.92762055 | AC6: =10+25+10+15 -> 60
B7: с52г/1 | C7: =VLOOKUP(B7,Setup!A:B,2,) -> Glossy Spray Cap, Vertical Spray, 52mm, Shape #1 | D7: Light Blue | E7: СР509 | G7: 35100 | H7: 35100 | I7: 11.3 | J7: 8.2 | K7: 8 | L7: =(60/I7)*K7 -> 42.477876 | M7: =15 -> 15 | N7: =15+15 -> 30 | Q7: =610+260 -> 870 | R7: =1.3+8.7 -> 10 | S7: =R7/(G7*J7/1000) -> 0.034743937 | T7: =(H7/(L7*(Q7-N7-M7-O7)))*((Q7-N7-M7-O7)/(Q7-N7-O7)) -> 0.98370536 | U7: =(H7*J7/(H7*J7+R7*1000)) -> 0.96642267 | V7: =T7*U7 -> 0.95067516 | AC7: =10+10 -> 20
B8: с52г/1 | C8: =VLOOKUP(B8,Setup!A:B,2,) -> Glossy Spray Cap, Vertical Spray, 52mm, Shape #1 | D8: Violet | E8: СР477 | G8: 40050 | H8: 40050 | I8: 11.3 | J8: 8.2 | K8: 8 | L8: =(60/I8)*K8 -> 42.477876 | M8: 20 | N8: 15 | Q8: =460+525 -> 985 | R8: 2 | S8: =R8/(G8*J8/1000) -> 0.0060899485 | T8: =(H8/(L8*(Q8-N8-M8-O8)))*((Q8-N8-M8-O8)/(Q8-N8-O8)) -> 0.97200387 | U8: =(H8*J8/(H8*J8+R8*1000)) -> 0.99394691 | V8: =T8*U8 -> 0.96612024 | AC8: 10
B9: с52г/1 | C9: =VLOOKUP(B9,Setup!A:B,2,) -> Glossy Spray Cap, Vertical Spray, 52mm, Shape #1 | D9: Pink-Crimson | E9: СР467 | G9: 80100 | H9: 80100 | I9: 11.3 | J9: 8.2 | K9: 8 | L9: =(60/I9)*K9 -> 42.477876 | M9: 20 | N9: =15+15 -> 30 | Q9: =195+720+720+330 -> 1965 | R9: =2.3+1.7+1 -> 5 | S9: =R9/(G9*J9/1000) -> 0.0076124357 | T9: =(H9/(L9*(Q9-N9-M9-O9)))*((Q9-N9-M9-O9)/(Q9-N9-O9)) -> 0.9745155 | U9: =(H9*J9/(H9*J9+R9*1000)) -> 0.99244508 | V9: =T9*U9 -> 0.96715311 | AC9: =10+10 -> 20
B10: с52г/1 | C10: =VLOOKUP(B10,Setup!A:B,2,) -> Glossy Spray Cap, Vertical Spray, 52mm, Shape #1 | D10: Green | E10: СР524 | G10: 40050 | H10: 40050 | I10: 11.3 | J10: 8.2 | K10: 8 | L10: =(60/I10)*K10 -> 42.477876 | M10: 30 | N10: 15 | Q10: =395+690 -> 1085 | R10: =10.7+2.3 -> 13 | S10: =R10/(G10*J10/1000) -> 0.039584666 | T10: =(H10/(L10*(Q10-N10-M10-O10)))*((Q10-N10-M10-O10)/(Q10-N10-O10)) -> 0.88116238 | U10: =(H10*J10/(H10*J10+R10*1000)) -> 0.96192262 | V10: =T10*U10 -> 0.84761002 | AC10: 25
B11: с52г/1 | C11: =VLOOKUP(B11,Setup!A:B,2,) -> Glossy Spray Cap, Vertical Spray, 52mm, Shape #1 | D11: Green | E11: СР045 | G11: 90000 | H11: 90000 | I11: 11.3 | J11: 8.2 | K11: 8 | L11: =(60/I11)*K11 -> 42.477876 | M11: 20 | N11: =15+15+15 -> 45 | Q11: =30+720+720+720 -> 2190 | R11: =7.6+1.2+3.1+0.8 -> 12.7 | S11: =R11/(G11*J11/1000) -> 0.017208672 | T11: =(H11/(L11*(Q11-N11-M11-O11)))*((Q11-N11-M11-O11)/(Q11-N11-O11)) -> 0.98776224 | U11: =(H11*J11/(H11*J11+R11*1000)) -> 0.98308246 | V11: =T11*U11 -> 0.97105173 | AC11: =25+15+10 -> 50
B12: с52г/1 | C12: =VLOOKUP(B12,Setup!A:B,2,) -> Glossy Spray Cap, Vertical Spray, 52mm, Shape #1 | D12: Violet | E12: СР044 | G12: 20250 | H12: 20250 | I12: 11.3 | J12: 8.2 | K12: 8 | L12: =(60/I12)*K12 -> 42.477876 | M12: 30 | N12: 30 | Q12: =510 -> 510 | R12: 8.3 | S12: =R12/(G12*J12/1000) -> 0.049984944 | T12: =(H12/(L12*(Q12-N12-M12-O12)))*((Q12-N12-M12-O12)/(Q12-N12-O12)) -> 0.99316406 | U12: =(H12*J12/(H12*J12+R12*1000)) -> 0.95239461 | V12: =T12*U12 -> 0.9458841 | AC12: 30
B13: с52г/1 | C13: =VLOOKUP(B13,Setup!A:B,2,) -> Glossy Spray Cap, Vertical Spray, 52mm, Shape #1 | D13: Blue | E13: СР429 | G13: 40050 | H13: 40050 | I13: 11.3 | J13: 8.2 | K13: 8 | L13: =(60/I13)*K13 -> 42.477876 | M13: 25 | Q13: =210+720+75 -> 1005 | R13: =7+3.6+1.7 -> 12.3 | S13: =R13/(G13*J13/1000) -> 0.037453184 | T13: =(H13/(L13*(Q13-N13-M13-O13)))*((Q13-N13-M13-O13)/(Q13-N13-O13)) -> 0.93815299 | U13: =(H13*J13/(H13*J13+R13*1000)) -> 0.96389892 | V13: =T13*U13 -> 0.90428465 | AC13: =25+10 -> 35
B14: с52г/1 | C14: =VLOOKUP(B14,Setup!A:B,2,) -> Glossy Spray Cap, Vertical Spray, 52mm, Shape #1 | D14: Lilac | E14: СР402 | G14: 40050 | H14: 40050 | I14: 11.3 | J14: 8.2 | K14: 8 | L14: =(60/I14)*K14 -> 42.477876 | M14: 20 | N14: 15 | Q14: =645+350 -> 995 | R14: =6+4 -> 10 | S14: =R14/(G14*J14/1000) -> 0.030449743 | T14: =(H14/(L14*(Q14-N14-M14-O14)))*((Q14-N14-M14-O14)/(Q14-N14-O14)) -> 0.96208546 | U14: =(H14*J14/(H14*J14+R14*1000)) -> 0.97045005 | V14: =T14*U14 -> 0.93365588 | AC14: 40
B15: с52г/1 | C15: =VLOOKUP(B15,Setup!A:B,2,) -> Glossy Spray Cap, Vertical Spray, 52mm, Shape #1 | D15: Violet | E15: СР477 | G15: =13050+87300 -> 100350 | H15: =13050+87300 -> 100350 | I15: 11.3 | J15: 8.2 | K15: 8 | L15: =(60/I15)*K15 -> 42.477876 | M15: 55 | N15: =15+15+15 -> 45 | Q15: =310+720+720+700 -> 2450 | R15: =2.6+1+1.5+3 -> 8.1 | S15: =R15/(G15*J15/1000) -> 0.0098435962 | T15: =(H15/(L15*(Q15-N15-M15-O15)))*((Q15-N15-M15-O15)/(Q15-N15-O15)) -> 0.9822895 | U15: =(H15*J15/(H15*J15+R15*1000)) -> 0.99025236 | V15: =T15*U15 -> 0.97271449 | AC15: =10+10+15 -> 35
B16: с52г/1 | C16: =VLOOKUP(B16,Setup!A:B,2,) -> Glossy Spray Cap, Vertical Spray, 52mm, Shape #1 | D16: Blue | E16: СР479 | G16: 30150 | H16: 30150 | I16: 11.3 | J16: 8.2 | K16: 8 | L16: =(60/I16)*K16 -> 42.477876 | M16: 20 | N16: 15 | Q16: =720+20 -> 740 | R16: =7.2+1.8 -> 9 | S16: =R16/(G16*J16/1000) -> 0.036403349 | T16: =(H16/(L16*(Q16-N16-M16-O16)))*((Q16-N16-M16-O16)/(Q16-N16-O16)) -> 0.97900862 | U16: =(H16*J16/(H16*J16+R16*1000)) -> 0.96487531 | V16: =T16*U16 -> 0.94462124 | AC16: 10
B17: с52г/1 | C17: =VLOOKUP(B17,Setup!A:B,2,) -> Glossy Spray Cap, Vertical Spray, 52mm, Shape #1 | D17: Ultramarine | E17: СР422 | G17: 45000 | H17: 45000 | I17: 11.3 | J17: 8.2 | K17: 8 | L17: =(60/I17)*K17 -> 42.477876 | M17: 20 | N17: 15 | Q17: =690+415 -> 1105 | R17: =6+1.2 -> 7.2 | S17: =R17/(G17*J17/1000) -> 0.019512195 | T17: =(H17/(L17*(Q17-N17-M17-O17)))*((Q17-N17-M17-O17)/(Q17-N17-O17)) -> 0.97190367 | U17: =(H17*J17/(H17*J17+R17*1000)) -> 0.98086124 | V17: =T17*U17 -> 0.95330264 | AC17: 10
B18: с52г/1 | C18: =VLOOKUP(B18,Setup!A:B,2,) -> Glossy Spray Cap, Vertical Spray, 52mm, Shape #1 | D18: Pink-Crimson | E18: СР467 | G18: 70200 | H18: 70200 | I18: 11.3 | J18: 8.2 | K18: 8 | L18: =(60/I18)*K18 -> 42.477876 | M18: 25 | N18: 15 | Q18: =305+720+720+40 -> 1785 | R18: =7.1+0.8+1.6+7.8 -> 17.3 | S18: =R18/(G18*J18/1000) -> 0.030053506 | T18: =(H18/(L18*(Q18-N18-M18-O18)))*((Q18-N18-M18-O18)/(Q18-N18-O18)) -> 0.93368644 | U18: =(H18*J18/(H18*J18+R18*1000)) -> 0.97082335 | V18: =T18*U18 -> 0.9064446 | AC18: 25
B19: с52г/1 | C19: =VLOOKUP(B19,Setup!A:B,2,) -> Glossy Spray Cap, Vertical Spray, 52mm, Shape #1 | D19: Blue | E19: СР524 | G19: 25200 | H19: 25200 | I19: 11.3 | J19: 8.2 | K19: 8 | L19: =(60/I19)*K19 -> 42.477876 | M19: 70 | N19: =15+15 -> 30 | Q19: =620+55 -> 675 | R19: 1.7 | S19: =R19/(G19*J19/1000) -> 0.008226868 | T19: =(H19/(L19*(Q19-N19-M19-O19)))*((Q19-N19-M19-O19)/(Q19-N19-O19)) -> 0.91976744 | U19: =(H19*J19/(H19*J19+R19*1000)) -> 0.99184026 | V19: =T19*U19 -> 0.91226238 | X19: 008 | Y19: 70 | AB19: Долгий выход на цвет | AC19: =25+15 -> 40
B20: с52г/1 | C20: =VLOOKUP(B20,Setup!A:B,2,) -> Glossy Spray Cap, Vertical Spray, 52mm, Shape #1 | D20: Pale Blue | E20: СР492 | G20: 35100 | H20: 35100 | I20: 11.3 | J20: 8.2 | K20: 8 | L20: =(60/I20)*K20 -> 42.477876 | M20: 30 | N20: 15 | Q20: =665+250 -> 915 | R20: =9+2.5 -> 11.5 | S20: =R20/(G20*J20/1000) -> 0.039955528 | T20: =(H20/(L20*(Q20-N20-M20-O20)))*((Q20-N20-M20-O20)/(Q20-N20-O20)) -> 0.918125 | U20: =(H20*J20/(H20*J20+R20*1000)) -> 0.96157958 | V20: =T20*U20 -> 0.88285025 | AC20: 25
B21: с52г/1 | C21: =VLOOKUP(B21,Setup!A:B,2,) -> Glossy Spray Cap, Vertical Spray, 52mm, Shape #1 | D21: Violet | E21: СР477 | G21: 40050 | H21: 40050 | I21: 11.3 | J21: 8.2 | K21: 8 | L21: =(60/I21)*K21 -> 42.477876 | M21: 50 | N21: 15 | Q21: =470+585 -> 1055 | R21: =13.9+5.4 -> 19.3 | S21: =R21/(G21*J21/1000) -> 0.058768003 | T21: =(H21/(L21*(Q21-N21-M21-O21)))*((Q21-N21-M21-O21)/(Q21-N21-O21)) -> 0.90658053 | U21: =(H21*J21/(H21*J21+R21*1000)) -> 0.94449397 | V21: =T21*U21 -> 0.85625985 | X21: 008 | Y21: 50 | AB21: Долгий выход на цвет | AC21: 15
B22: с52г/1 | C22: =VLOOKUP(B22,Setup!A:B,2,) -> Glossy Spray Cap, Vertical Spray, 52mm, Shape #1 | D22: Orange | E22: СР507 | G22: 19350 | H22: 19350 | I22: 11.3 | J22: 8.2 | K22: 8 | L22: =(60/I22)*K22 -> 42.477876 | M22: 15 | N22: 15 | Q22: =135+365 -> 500 | R22: =7.7+0.7 -> 8.4 | S22: =R22/(G22*J22/1000) -> 0.052940064 | T22: =(H22/(L22*(Q22-N22-M22-O22)))*((Q22-N22-M22-O22)/(Q22-N22-O22)) -> 0.93923969 | U22: =(H22*J22/(H22*J22+R22*1000)) -> 0.94972167 | V22: =T22*U22 -> 0.89201629 | AC22: 10
B23: с52г/1 | C23: =VLOOKUP(B23,Setup!A:B,2,) -> Glossy Spray Cap, Vertical Spray, 52mm, Shape #1 | D23: Pink-Crimson | E23: СР467 | G23: =42300+117900 -> 160200 | H23: =42300+117900 -> 160200 | I23: 11.3 | J23: 8.2 | K23: 8 | L23: =(60/I23)*K23 -> 42.477876 | M23: 20 | N23: =15+15+15+15+15+15 -> 90 | Q23: =355+720+720+720+665+720+190+55 -> 4145 | R23: =6.9+1.7+2.5+1.7+7+1+1.3 -> 22.1 | S23: =R23/(G23*J23/1000) -> 0.016823483 | T23: =(H23/(L23*(Q23-N23-M23-O23)))*((Q23-N23-M23-O23)/(Q23-N23-O23)) -> 0.93005549 | U23: =(H23*J23/(H23*J23+R23*1000)) -> 0.98345486 | V23: =T23*U23 -> 0.91466759 | X23: 017 | Y23: 55 | AB23: ремонт ПФ | AC23: =25+20+25+25+10+15 -> 120
B24: с52г/1 | C24: =VLOOKUP(B24,Setup!A:B,2,) -> Glossy Spray Cap, Vertical Spray, 52mm, Shape #1 | D24: Crimson | E24: СР508 | G24: 43200 | H24: 43200 | I24: 11.3 | J24: 8.2 | K24: 8 | L24: =(60/I24)*K24 -> 42.477876 | M24: 20 | N24: 15 | Q24: =530+530 -> 1060 | R24: =7+0.8 -> 7.8 | S24: =R24/(G24*J24/1000) -> 0.02201897 | T24: =(H24/(L24*(Q24-N24-M24-O24)))*((Q24-N24-M24-O24)/(Q24-N24-O24)) -> 0.97320574 | U24: =(H24*J24/(H24*J24+R24*1000)) -> 0.97845542 | V24: =T24*U24 -> 0.95223843 | AC24: 10
B25: с52г/1 | C25: =VLOOKUP(B25,Setup!A:B,2,) -> Glossy Spray Cap, Vertical Spray, 52mm, Shape #1 | D25: Violet | E25: СР503 | G25: 43200 | H25: 43200 | I25: 11.3 | J25: 8.2 | K25: 8 | L25: =(60/I25)*K25 -> 42.477876 | M25: 20 | N25: 15 | Q25: =190+720+165 -> 1075 | R25: =6.9+2.2+2.5 -> 11.6 | S25: =R25/(G25*J25/1000) -> 0.032746161 | T25: =(H25/(L25*(Q25-N25-M25-O25)))*((Q25-N25-M25-O25)/(Q25-N25-O25)) -> 0.95943396 | U25: =(H25*J25/(H25*J25+R25*1000)) -> 0.96829215 | V25: =T25*U25 -> 0.92901237 | AC25: 25
B26: с52г/1 | C26: =VLOOKUP(B26,Setup!A:B,2,) -> Glossy Spray Cap, Vertical Spray, 52mm, Shape #1 | D26: Pale Blue | E26: СР492 | G26: 196650 | H26: 196650 | I26: 11.3 | J26: 8.2 | K26: 8 | L26: =(60/I26)*K26 -> 42.477876 | M26: 15 | N26: =15+15+15+15+15 -> 75 | Q26: =555+720+720+720+720+720+720+30 -> 4905 | R26: =4.9+3.6+0.9+1.8+1.7+2.1+4.7+2.7+3.7 -> 26.1 | S26: =R26/(G26*J26/1000) -> 0.016185745 | T26: =(H26/(L26*(Q26-N26-M26-O26)))*((Q26-N26-M26-O26)/(Q26-N26-O26)) -> 0.95848214 | U26: =(H26*J26/(H26*J26+R26*1000)) -> 0.98407206 | V26: =T26*U26 -> 0.9432155 | AC26: =15+15+25+15+25 -> 95
G27: =SUM(G2:G26) -> 1570500 | H27: =SUM(H2:H26) -> 1570500 | M27: =SUM(M2:M26) -> 765 | N27: =SUM(N2:N26) -> 720 | O27: =SUM(O2:O26) -> 535 | Q27: =SUM(Q2:Q26) -> 40235 | R27: =SUM(R2:R26) -> 273.8

Sheet 3
A1: Injection molding machine number | B1: Type of cap | C1: Type of cap | D1: Color of the cap | E1: Cap code | F1: номер партии | G1: Planned production, pcs | H1: Actual production, pcs | I1: Target cycle time, seconds | J1: Target weight of cap, grams. | K1: Number of cavities in the mold | L1: Target productivity per minute, pcs. | M1: Time for transition (including replacement of the mold), min. | N1: Time for daily maintenance of the mold, min | O1: Other stops not dependent on operating personnel, min | P1: Description of the reason for stopping column "N", "L" | Q1: Total batch production time, min | R1: Defective raw materials, kg | S1: Percentage of defective materials | T1: ОЕЕ1 | U1: ОЕЕ2 | V1: ОЕЕ | X1: Код простоя, TDE. | Y1: Прочие остановки, мин. | Z1: Код простоя, TDE. | AA1: Прочие остановки, мин. | AB1: Описание причины остановки столбик "R; T" | AC1: Время на ежесменное техническое обслуживание пресс-формы, мин.
A2: 3 | B2: с52г/1 | C2: =VLOOKUP(B2,Setup!A:B,2,) -> Glossy Spray Cap, Vertical Spray, 52mm, Shape #1 | D2: Green | E2: СР045 | G2: 90000 | H2: 90000 | I2: 11.3 | J2: 8.2 | K2: 8 | L2: =(60/I2)*K2 -> 42.477876 | M2: 70 | N2: =15+15+15 -> 45 | Q2: =620+720+720+200+70 -> 2330 | R2: =7.4+1.3+0.7+0.7 -> 10.1 | S2: =R2/(G2*J2/1000) -> 0.013685637 | T2: =(H2/(L2*(Q2-N2-M2-O2)))*((Q2-N2-M2-O2)/(Q2-N2-O2)) -> 0.92724289 | U2: =(H2*J2/(H2*J2+R2*1000)) -> 0.98649913 | V2: =T2*U2 -> 0.9147243 | X2: 001 | Y2: 70 | AC2: =10+10+10 -> 30
B3: с52г/1 | C3: =VLOOKUP(B3,Setup!A:B,2,) -> Glossy Spray Cap, Vertical Spray, 52mm, Shape #1 | D3: Green | E3: СР524 | G3: 50400 | H3: 50400 | I3: 11.3 | J3: 8.2 | K3: 8 | L3: =(60/I3)*K3 -> 42.477876 | M3: 15 | N3: =15+15 -> 30 | Q3: =530+720+55 -> 1305 | R3: =4.9+1.3+7.6 -> 13.8 | S3: =R3/(G3*J3/1000) -> 0.033391405 | T3: =(H3/(L3*(Q3-N3-M3-O3)))*((Q3-N3-M3-O3)/(Q3-N3-O3)) -> 0.93058824 | U3: =(H3*J3/(H3*J3+R3*1000)) -> 0.96768755 | V3: =T3*U3 -> 0.90051865 | AC3: =25+10 -> 35
B4: с52г/1 | C4: =VLOOKUP(B4,Setup!A:B,2,) -> Glossy Spray Cap, Vertical Spray, 52mm, Shape #1 | D4: Lime | E4: СР431 | G4: 20250 | H4: 20250 | I4: 11.3 | J4: 8.2 | K4: 8 | L4: =(60/I4)*K4 -> 42.477876 | M4: =20 -> 20 | Q4: 505 | R4: 9.3 | S4: =R4/(G4*J4/1000) -> 0.056007227 | T4: =(H4/(L4*(Q4-N4-M4-O4)))*((Q4-N4-M4-O4)/(Q4-N4-O4)) -> 0.94399752 | U4: =(H4*J4/(H4*J4+R4*1000)) -> 0.94696322 | V4: =T4*U4 -> 0.89393093
B5: с52г/1 | C5: =VLOOKUP(B5,Setup!A:B,2,) -> Glossy Spray Cap, Vertical Spray, 52mm, Shape #1 | D5: Pink | E5: СР430 | G5: 20250 | H5: 20250 | I5: 11.3 | J5: 8.2 | K5: 8 | L5: =(60/I5)*K5 -> 42.477876 | M5: =30 -> 30 | N5: 15 | Q5: =100+445 -> 545 | R5: =2.2+2.2+0.36 -> 4.76 | S5: =R5/(G5*J5/1000) -> 0.028666064 | T5: =(H5/(L5*(Q5-N5-M5-O5)))*((Q5-N5-M5-O5)/(Q5-N5-O5)) -> 0.89946934 | U5: =(H5*J5/(H5*J5+R5*1000)) -> 0.97213278 | V5: =T5*U5 -> 0.87440363 | X5: 005 | Y5: 95 | AC5: 25
B6: с35м/дм | C6: =VLOOKUP(B6,Setup!A:B,2,) -> Dispenser - Component of 35mm Hair Styling Mousse Dispenser | D6: Black | E6: СР534/1 | G6: 100500 | H6: 100500 | I6: 19.35 | J6: 3.3 | K6: 12 | L6: =(60/I6)*K6 -> 37.209302 | M6: 95 | N6: =15+15+15+15 -> 60 | P6: replacement of the mold | Q6: =500+720+720+720+140+95 -> 2895 | R6: =0.5+2+0.6+0.6 -> 3.7 | S6: =R6/(G6*J6/1000) -> 0.01115634 | T6: =(H6/(L6*(Q6-N6-M6-O6)))*((Q6-N6-M6-O6)/(Q6-N6-O6)) -> 0.95271164 | U6: =(H6*J6/(H6*J6+R6*1000)) -> 0.98896675 | V6: =T6*U6 -> 0.94220014 | X6: 006 | Y6: 180 | Z6: 015 | AA6: 60 | AB6: тесты красителя,простой, замерший гор.канал | AC6: =10+10+10+10 -> 40
B7: з52г | C7: =VLOOKUP(B7,Setup!A:B,2,) -> Glossy Protective Cap, 52mm | D7: Cherry | E7: СР220 | G7: 100350 | H7: 100350 | I7: 7.5 | J7: 6 | K7: 8 | L7: =(60/I7)*K7 -> 64 | M7: 135 | N7: =15+15 -> 30 | P7: replacement of the mold | Q7: =120+135+720+700+165 -> 1840 | R7: =4.4+1.5+5.5+1.4 -> 12.8 | S7: =R7/(G7*J7/1000) -> 0.021258927 | T7: =(H7/(L7*(Q7-N7-M7-O7)))*((Q7-N7-M7-O7)/(Q7-N7-O7)) -> 0.86628108 | U7: =(H7*J7/(H7*J7+R7*1000)) -> 0.97918361 | V7: =T7*U7 -> 0.84824823 | X7: 015 | Y7: 20 | Z7: 005 | AA7: 135 | AB7: тесты красителя, замена ПФ,замерший гор.канал | AC7: =20+10 -> 30
B8: з52г | C8: =VLOOKUP(B8,Setup!A:B,2,) -> Glossy Protective Cap, 52mm | D8: Violet | E8: CP219 | G8: 70200 | H8: 70200 | I8: 7.5 | J8: 6 | K8: 8 | L8: =(60/I8)*K8 -> 64 | M8: 20 | N8: =15 -> 15 | Q8: =525+645+75 -> 1245 | R8: =7.8 -> 7.8 | S8: =R8/(G8*J8/1000) -> 0.018518519 | T8: =(H8/(L8*(Q8-N8-M8-O8)))*((Q8-N8-M8-O8)/(Q8-N8-O8)) -> 0.89176829 | U8: =(H8*J8/(H8*J8+R8*1000)) -> 0.98181818 | V8: =T8*U8 -> 0.87555432 | X8: 008 | Y8: 75 | AB8: настройка дозатора | AC8: =10 -> 10
B9: з52г | C9: =VLOOKUP(B9,Setup!A:B,2,) -> Glossy Protective Cap, 52mm | D9: Blue | E9: СР452 | G9: 43200 | H9: 43200 | I9: 7.5 | J9: 6 | K9: 8 | L9: =(60/I9)*K9 -> 64 | M9: 75 | N9: 15 | Q9: =720 -> 720 | R9: =12.4+0.6 -> 13 | S9: =R9/(G9*J9/1000) -> 0.050154321 | T9: =(H9/(L9*(Q9-N9-M9-O9)))*((Q9-N9-M9-O9)/(Q9-N9-O9)) -> 0.95744681 | U9: =(H9*J9/(H9*J9+R9*1000)) -> 0.952241 | V9: =T9*U9 -> 0.91172011 | AC9: 10
B10: з52г | C10: =VLOOKUP(B10,Setup!A:B,2,) -> Glossy Protective Cap, 52mm | D10: Ultramarine | E10: СР162 | G10: 36000 | H10: 36000 | I10: 7.5 | J10: 6 | K10: 8 | L10: =(60/I10)*K10 -> 64 | M10: 20 | N10: =15 -> 15 | Q10: 620 | R10: =7.4 -> 7.4 | S10: =R10/(G10*J10/1000) -> 0.034259259 | T10: =(H10/(L10*(Q10-N10-M10-O10)))*((Q10-N10-M10-O10)/(Q10-N10-O10)) -> 0.92975207 | U10: =(H10*J10/(H10*J10+R10*1000)) -> 0.96687556 | V10: =T10*U10 -> 0.89895455 | AC10: =15 -> 15
B11: з52г | C11: =VLOOKUP(B11,Setup!A:B,2,) -> Glossy Protective Cap, 52mm | D11: Blueberry | E11: СР453 | G11: 45000 | H11: 45000 | I11: 7.5 | J11: 6 | K11: 8 | L11: =(60/I11)*K11 -> 64 | M11: 20 | N11: 15 | Q11: =60+720 -> 780 | R11: =6.4+1.7 -> 8.1 | S11: =R11/(G11*J11/1000) -> 0.03 | T11: =(H11/(L11*(Q11-N11-M11-O11)))*((Q11-N11-M11-O11)/(Q11-N11-O11)) -> 0.91911765 | U11: =(H11*J11/(H11*J11+R11*1000)) -> 0.97087379 | V11: =T11*U11 -> 0.89234723 | AC11: =10 -> 10
B12: з52г | C12: =VLOOKUP(B12,Setup!A:B,2,) -> Glossy Protective Cap, 52mm | D12: Black | E12: СР268 | G12: 46350 | H12: 46350 | I12: 7.5 | J12: 6 | K12: 8 | L12: =(60/I12)*K12 -> 64 | M12: 20 | N12: 15 | Q12: =720+70 -> 790 | R12: =1.5 -> 1.5 | S12: =R12/(G12*J12/1000) -> 0.0053937433 | T12: =(H12/(L12*(Q12-N12-M12-O12)))*((Q12-N12-M12-O12)/(Q12-N12-O12)) -> 0.93447581 | U12: =(H12*J12/(H12*J12+R12*1000)) -> 0.99463519 | V12: =T12*U12 -> 0.92946252 | X12: 005 | Y12: 90 | AB12: замена ПФ | AC12: 25
B13: з45г | C13: =VLOOKUP(B13,Setup!A:B,2,) -> Glossy Protective Cap, 45mm | D13: Blue | E13: CP324 | G13: 40200 | H13: 40200 | I13: 7.8 | J13: 5 | K13: 8 | L13: =(60/I13)*K13 -> 61.538462 | M13: =20+90 -> 110 | P13: replacement of the mold | Q13: =540+110+110 -> 760 | R13: =10.3 -> 10.3 | S13: =R13/(G13*J13/1000) -> 0.051243781 | T13: =(H13/(L13*(Q13-N13-M13-O13)))*((Q13-N13-M13-O13)/(Q13-N13-O13)) -> 0.85953947 | U13: =(H13*J13/(H13*J13+R13*1000)) -> 0.95125414 | V13: =T13*U13 -> 0.81764048 | X13: 005 | Y13: 150 | AB13: замена ПФ
B14: с52м/3 | C14: =VLOOKUP(B14,Setup!A:B,2,) -> Matte Spray Cap horizontal spray 52mm | D14: Black | E14: СР488 | G14: =97200+103200 -> 200400 | H14: =97200+103200 -> 200400 | I14: 12 | J14: 6 | K14: 8 | L14: =(60/I14)*K14 -> 40 | M14: 150 | N14: =15+15+15+15+15+15+15 -> 105 | P14: replacement of the mold | Q14: =460+150+720+720+720+720+720+720+610 -> 5540 | R14: =5.1+1.2+1+0.6+0.9+0.2+1.2+0.3+0.5 -> 11 | S14: =R14/(G14*J14/1000) -> 0.0091483699 | T14: =(H14/(L14*(Q14-N14-M14-O14)))*((Q14-N14-M14-O14)/(Q14-N14-O14)) -> 0.92180313 | U14: =(H14*J14/(H14*J14+R14*1000)) -> 0.99093456 | V14: =T14*U14 -> 0.91344658 | X14: 005 | Y14: 120 | AB14: замена ПФ | AC14: =10+10+10+10+10+10+10 -> 70
B15: з65г/м | C15: =VLOOKUP(B15,Setup!A:B,2,) -> Protective Cap for Freshmatic 65mm | D15: Green | E15: СР512 | G15: 230040 | H15: 230040 | I15: 9.4 | J15: 8.3 | K15: 8 | L15: =(60/I15)*K15 -> 51.06383 | M15: 120 | N15: =15+15+15+15+15+15 -> 90 | P15: replacement of the mold | Q15: =120+720+720+720+720+720+720+375 -> 4815 | R15: =6.1+0.2+0.6+0.6+0.4+0.8+0.4+5.1 -> 14.2 | S15: =R15/(G15*J15/1000) -> 0.007437156 | T15: =(H15/(L15*(Q15-N15-M15-O15)))*((Q15-N15-M15-O15)/(Q15-N15-O15)) -> 0.95342857 | U15: =(H15*J15/(H15*J15+R15*1000)) -> 0.99261775 | V15: =T15*U15 -> 0.94639012 | X15: 005 | Y15: 120 | Z15: 001 | AA15: 15 | AB15: замена ПФ | AC15: =10+10+10+10+10+10 -> 60
B16: с52г/1 | C16: =VLOOKUP(B16,Setup!A:B,2,) -> Glossy Spray Cap, Vertical Spray, 52mm, Shape #1 | D16: Beige | E16: СР428 | G16: 35100 | H16: 35100 | I16: 11.3 | J16: 8.2 | K16: 8 | L16: =(60/I16)*K16 -> 42.477876 | M16: =110+55 -> 165 | N16: =15+15 -> 30 | P16: replacement of the mold | Q16: =235+110+720 -> 1065 | R16: =9.7 -> 9.7 | S16: =R16/(G16*J16/1000) -> 0.033701619 | T16: =(H16/(L16*(Q16-N16-M16-O16)))*((Q16-N16-M16-O16)/(Q16-N16-O16)) -> 0.79836957 | U16: =(H16*J16/(H16*J16+R16*1000)) -> 0.96739715 | V16: =T16*U16 -> 0.77234044 | X16: 005 | Y16: 90 | AB16: замена ПФ | AC16: =10+10 -> 20
B17: с52г/1 | C17: =VLOOKUP(B17,Setup!A:B,2,) -> Glossy Spray Cap, Vertical Spray, 52mm, Shape #1 | D17: Ultramarine | E17: СР422 | G17: 25200 | H17: 25200 | I17: 11.3 | J17: 8.2 | K17: 8 | L17: =(60/I17)*K17 -> 42.477876 | M17: 30 | N17: =15 -> 15 | Q17: =635 -> 635 | R17: =10.6 -> 10.6 | S17: =R17/(G17*J17/1000) -> 0.051296942 | T17: =(H17/(L17*(Q17-N17-M17-O17)))*((Q17-N17-M17-O17)/(Q17-N17-O17)) -> 0.95685484 | U17: =(H17*J17/(H17*J17+R17*1000)) -> 0.95120604 | V17: =T17*U17 -> 0.9101661 | AC17: =10 -> 10
B18: с52г/1 | C18: =VLOOKUP(B18,Setup!A:B,2,) -> Glossy Spray Cap, Vertical Spray, 52mm, Shape #1 | D18: Turquoise | E18: СР505 | G18: 22050 | H18: 22050 | I18: 11.3 | J18: 8.2 | K18: 8 | L18: =(60/I18)*K18 -> 42.477876 | M18: 20 | N18: =15 -> 15 | Q18: =65+495 -> 560 | R18: =6.1+1.6 -> 7.7 | S18: =R18/(G18*J18/1000) -> 0.04258614 | T18: =(H18/(L18*(Q18-N18-M18-O18)))*((Q18-N18-M18-O18)/(Q18-N18-O18)) -> 0.9524656 | U18: =(H18*J18/(H18*J18+R18*1000)) -> 0.95915336 | V18: =T18*U18 -> 0.91356058 | AC18: =25 -> 25
B19: с52г/1 | C19: =VLOOKUP(B19,Setup!A:B,2,) -> Glossy Spray Cap, Vertical Spray, 52mm, Shape #1 | D19: Green | E19: СР504 | G19: =8550+14850 -> 23400 | H19: =8550+14850 -> 23400 | I19: 11.3 | J19: 8.2 | K19: 8 | L19: =(60/I19)*K19 -> 42.477876 | M19: 20 | N19: 15 | Q19: =205+375 -> 580 | R19: =5.4+0.7 -> 6.1 | S19: =R19/(G19*J19/1000) -> 0.031790703 | T19: =(H19/(L19*(Q19-N19-M19-O19)))*((Q19-N19-M19-O19)/(Q19-N19-O19)) -> 0.975 | U19: =(H19*J19/(H19*J19+R19*1000)) -> 0.96918881 | V19: =T19*U19 -> 0.94495909 | AC19: =10 -> 10
B20: с52г/1 | C20: =VLOOKUP(B20,Setup!A:B,2,) -> Glossy Spray Cap, Vertical Spray, 52mm, Shape #1 | D20: Green | E20: СР524 | G20: 70200 | H20: 70200 | I20: 11.3 | J20: 8.2 | K20: 8 | L20: =(60/I20)*K20 -> 42.477876 | M20: 20 | N20: =15+15 -> 30 | Q20: =325+720+700 -> 1745 | R20: =7.1+2.1+0.9 -> 10.1 | S20: =R20/(G20*J20/1000) -> 0.017545688 | T20: =(H20/(L20*(Q20-N20-M20-O20)))*((Q20-N20-M20-O20)/(Q20-N20-O20)) -> 0.96362974 | U20: =(H20*J20/(H20*J20+R20*1000)) -> 0.98275685 | V20: =T20*U20 -> 0.94701373 | AC20: =25+10 -> 35
B21: с52г/1 | C21: =VLOOKUP(B21,Setup!A:B,2,) -> Glossy Spray Cap, Vertical Spray, 52mm, Shape #1 | D21: Green | E21: СР045 | G21: 60300 | H21: 60300 | I21: 11.3 | J21: 8.2 | K21: 8 | L21: =(60/I21)*K21 -> 42.477876 | M21: 20 | N21: =15+15 -> 30 | Q21: =720+720+50 -> 1490 | R21: =8.3+0.96 -> 9.26 | S21: =R21/(G21*J21/1000) -> 0.018727501 | T21: =(H21/(L21*(Q21-N21-M21-O21)))*((Q21-N21-M21-O21)/(Q21-N21-O21)) -> 0.97230308 | U21: =(H21*J21/(H21*J21+R21*1000)) -> 0.98161677 | V21: =T21*U21 -> 0.95442901 | AC21: =10+10 -> 20
B22: с52г/1 | C22: =VLOOKUP(B22,Setup!A:B,2,) -> Glossy Spray Cap, Vertical Spray, 52mm, Shape #1 | D22: Green | E22: СР524 | G22: 80100 | H22: 80100 | I22: 11.3 | J22: 8.2 | K22: 8 | L22: =(60/I22)*K22 -> 42.477876 | M22: 25 | N22: =15+15 -> 30 | Q22: =635+720+615 -> 1970 | R22: =8.2+1.1+1.05 -> 10.35 | S22: =R22/(G22*J22/1000) -> 0.015757742 | T22: =(H22/(L22*(Q22-N22-M22-O22)))*((Q22-N22-M22-O22)/(Q22-N22-O22)) -> 0.97200387 | U22: =(H22*J22/(H22*J22+R22*1000)) -> 0.98448671 | V22: =T22*U22 -> 0.95692489 | AC22: =10+15 -> 25
B23: с52г/1 | C23: =VLOOKUP(B23,Setup!A:B,2,) -> Glossy Spray Cap, Vertical Spray, 52mm, Shape #1 | D23: Blue | E23: СР509 | G23: 43200 | H23: 43200 | I23: 11.3 | J23: 8.2 | K23: 8 | L23: =(60/I23)*K23 -> 42.477876 | M23: 30 | N23: 15 | Q23: =75+720+260 -> 1055 | R23: =6.96+1.1+0.8 -> 8.86 | S23: =R23/(G23*J23/1000) -> 0.025011292 | T23: =(H23/(L23*(Q23-N23-M23-O23)))*((Q23-N23-M23-O23)/(Q23-N23-O23)) -> 0.97788462 | U23: =(H23*J23/(H23*J23+R23*1000)) -> 0.97559901 | V23: =T23*U23 -> 0.95402326 | AC23: =10 -> 10
B24: с52г/1 | C24: =VLOOKUP(B24,Setup!A:B,2,) -> Glossy Spray Cap, Vertical Spray, 52mm, Shape #1 | D24: Blue | E24: СР429 | G24: 34200 | H24: 34200 | I24: 11.3 | J24: 8.2 | K24: 8 | L24: =(60/I24)*K24 -> 42.477876 | M24: 35 | N24: =15 -> 15 | Q24: =415+430 -> 845 | R24: =10.65+1.5 -> 12.15 | S24: =R24/(G24*J24/1000) -> 0.043324775 | T24: =(H24/(L24*(Q24-N24-M24-O24)))*((Q24-N24-M24-O24)/(Q24-N24-O24)) -> 0.97003012 | U24: =(H24*J24/(H24*J24+R24*1000)) -> 0.95847432 | V24: =T24*U24 -> 0.92974896 | AC24: =25 -> 25
B25: с52г/1 | C25: =VLOOKUP(B25,Setup!A:B,2,) -> Glossy Spray Cap, Vertical Spray, 52mm, Shape #1 | D25: Lilac | E25: СР402 | G25: 34200 | H25: 34200 | I25: 11.3 | J25: 8.2 | K25: 8 | L25: =(60/I25)*K25 -> 42.477876 | M25: 30 | N25: 15 | Q25: =260+580 -> 840 | R25: =11 -> 11 | S25: =R25/(G25*J25/1000) -> 0.039224076 | T25: =(H25/(L25*(Q25-N25-M25-O25)))*((Q25-N25-M25-O25)/(Q25-N25-O25)) -> 0.97590909 | U25: =(H25*J25/(H25*J25+R25*1000)) -> 0.96225638 | V25: =T25*U25 -> 0.93907475 | AC25: 10
B26: с52г/1 | C26: =VLOOKUP(B26,Setup!A:B,2,) -> Glossy Spray Cap, Vertical Spray, 52mm, Shape #1 | D26: Violet | E26: СР477 | G26: 63900 | H26: 63900 | I26: 11.3 | J26: 8.2 | K26: 8 | L26: =(60/I26)*K26 -> 42.477876 | M26: 30 | N26: =15+15 -> 30 | Q26: =110+720+720 -> 1550 | R26: =11.2+1.2+1.6 -> 14 | S26: =R26/(G26*J26/1000) -> 0.026718577 | T26: =(H26/(L26*(Q26-N26-M26-O26)))*((Q26-N26-M26-O26)/(Q26-N26-O26)) -> 0.98967928 | U26: =(H26*J26/(H26*J26+R26*1000)) -> 0.97397673 | V26: =T26*U26 -> 0.96392458 | AC26: =25+10 -> 35
G27: =SUM(G2:G26) -> 1584990 | H27: =SUM(H2:H26) -> 1584990 | M27: =SUM(M2:M26) -> 1325 | N27: =SUM(N2:N26) -> 690 | O27: =SUM(O2:O26) -> 0 | Q27: =SUM(Q2:Q26) -> 37025 | R27: =SUM(R2:R26) -> 237.58

Sheet 4
A1: Injection molding machine number | B1: Type of cap | C1: Type of cap | D1: Color of the cap | E1: Cap code | F1: номер партии | G1: Planned production, pcs | H1: Actual production, pcs | I1: Target cycle time, seconds | J1: Target weight of cap, grams. | K1: Number of cavities in the mold | L1: Target productivity per minute, pcs. | M1: Time for transition (including replacement of the mold), min. | N1: Time for daily maintenance of the mold, min | O1: Other stops not dependent on operating personnel, min | P1: Description of the reason for stopping column "N", "L" | Q1: Total batch production time, min | R1: Defective raw materials, kg | S1: Percentage of defective materials | T1: ОЕЕ1 | U1: ОЕЕ2 | V1: ОЕЕ | X1: Код простоя, TDE. | Y1: Прочие остановки, мин. | Z1: Код простоя, TDE. | AA1: Прочие остановки, мин. | AB1: Описание причины остановки столбик "R; T" | AC1: Время на ежесменное техническое обслуживание пресс-формы, мин.
A2: 4 | B2: з65г | C2: =VLOOKUP(B2,Setup!A:B,2,) -> Glossy Protective Cap, 65mm | D2: Turquoise | E2: СР530 | G2: 32130 | H2: 32130 | I2: 8.5 | J2: 9 | K2: 8 | L2: =(60/I2)*K2 -> 56.470588 | M2: 120 | Q2: =600+120 -> 720 | R2: =11.1+1.9 -> 13 | S2: =R2/(G2*J2/1000) -> 0.044956254 | T2: =(H2/(L2*(Q2-N2-M2-O2)))*((Q2-N2-M2-O2)/(Q2-N2-O2)) -> 0.79023438 | U2: =(H2*J2/(H2*J2+R2*1000)) -> 0.95697786 | V2: =T2*U2 -> 0.7562368 | X2: 001 | Y2: 120 | AB2: запуск в начале смены
B3: з65г | C3: =VLOOKUP(B3,Setup!A:B,2,) -> Glossy Protective Cap, 65mm | D3: Royal Blue | E3: СР531 | G3: 20250 | H3: 20250 | I3: 8.5 | J3: 9 | K3: 8 | L3: =(60/I3)*K3 -> 56.470588 | M3: 15 | N3: 15 | Q3: 395 | R3: 7.3 | S3: =R3/(G3*J3/1000) -> 0.04005487 | T3: =(H3/(L3*(Q3-N3-M3-O3)))*((Q3-N3-M3-O3)/(Q3-N3-O3)) -> 0.94366776 | U3: =(H3*J3/(H3*J3+R3*1000)) -> 0.96148773 | V3: =T3*U3 -> 0.90732498 | AC3: 10
B4: з65г | C4: =VLOOKUP(B4,Setup!A:B,2,) -> Glossy Protective Cap, 65mm | D4: Light Green | E4: СР533 | G4: 32130 | H4: 32130 | I4: 8.5 | J4: 9 | K4: 8 | L4: =(60/I4)*K4 -> 56.470588 | M4: 20 | N4: 15 | Q4: =325+290 -> 615 | R4: =10.6+5.4 -> 16 | S4: =R4/(G4*J4/1000) -> 0.055330774 | T4: =(H4/(L4*(Q4-N4-M4-O4)))*((Q4-N4-M4-O4)/(Q4-N4-O4)) -> 0.94828125 | U4: =(H4*J4/(H4*J4+R4*1000)) -> 0.94757021 | V4: =T4*U4 -> 0.89856306 | AC4: 15
B5: з65г | C5: =VLOOKUP(B5,Setup!A:B,2,) -> Glossy Protective Cap, 65mm | D5: Olive | E5: CP436 | G5: 14310 | H5: 14310 | I5: 8.5 | J5: 9 | K5: 8 | L5: =(60/I5)*K5 -> 56.470588 | M5: 15 | Q5: 280 | R5: 2.3 | S5: =R5/(G5*J5/1000) -> 0.017858529 | T5: =(H5/(L5*(Q5-N5-M5-O5)))*((Q5-N5-M5-O5)/(Q5-N5-O5)) -> 0.90502232 | U5: =(H5*J5/(H5*J5+R5*1000)) -> 0.9824548 | V5: =T5*U5 -> 0.88914353
C6: сломался ТПА
G7: =SUM(G2:G6) -> 98820 | H7: =SUM(H2:H6) -> 98820 | M7: =SUM(M2:M6) -> 170 | N7: =SUM(N2:N6) -> 30 | O7: =SUM(O2:O6) -> 0 | Q7: =SUM(Q2:Q6) -> 2010 | R7: =SUM(R2:R6) -> 38.6

Sheet 5
A1: Injection molding machine number | B1: Type of cap | C1: Type of cap | D1: Color of the cap | E1: Cap code | F1: номер партии | G1: Planned production, pcs | H1: Actual production, pcs | I1: Target cycle time, seconds | J1: Target weight of cap, grams. | K1: Number of cavities in the mold | L1: Target productivity per minute, pcs. | M1: Time for transition (including replacement of the mold), min. | N1: Time for daily maintenance of the mold, min | O1: Other stops not dependent on operating personnel, min | P1: Description of the reason for stopping column "N", "L" | Q1: Total batch production time, min | R1: Defective raw materials, kg | S1: Percentage of defective materials | T1: ОЕЕ1 | U1: ОЕЕ2 | V1: ОЕЕ | X1: Код простоя, TDE. | Y1: Прочие остановки, мин. | Z1: Код простоя, TDE. | AA1: Прочие остановки, мин. | AB1: Описание причины остановки столбик "R; T" | AC1: Время на ежесменное техническое обслуживание пресс-формы, мин.
A2: 5 | B2: з65г | C2: =VLOOKUP(B2,Setup!A:B,2,) -> Glossy Protective Cap, 65mm | D2: yellow | E2: CP434 | G2: 32130 | H2: 32130 | I2: 8.5 | J2: 9 | K2: 8 | L2: =(60/I2)*K2 -> 56.470588 | M2: 40 | N2: 15 | Q2: =520+65+40 -> 625 | R2: =6.3+4.1 -> 10.4 | S2: =R2/(G2*J2/1000) -> 0.035965003 | T2: =(H2/(L2*(Q2-N2-M2-O2)))*((Q2-N2-M2-O2)/(Q2-N2-O2)) -> 0.93273566 | U2: =(H2*J2/(H2*J2+R2*1000)) -> 0.96528357 | V2: =T2*U2 -> 0.90035441 | X2: 001 | Y2: 40 | AC2: =10 -> 10
B3: з65г | C3: =VLOOKUP(B3,Setup!A:B,2,) -> Glossy Protective Cap, 65mm | D3: orange | E3: СР474 | G3: 20250 | H3: 20250 | I3: 8.5 | J3: 9 | K3: 8 | L3: =(60/I3)*K3 -> 56.470588 | M3: 10 | Q3: =365 -> 365 | R3: =4.9 -> 4.9 | S3: =R3/(G3*J3/1000) -> 0.026886145 | T3: =(H3/(L3*(Q3-N3-M3-O3)))*((Q3-N3-M3-O3)/(Q3-N3-O3)) -> 0.98244863 | U3: =(H3*J3/(H3*J3+R3*1000)) -> 0.97381779 | V3: =T3*U3 -> 0.95672596
B4: з65г | C4: =VLOOKUP(B4,Setup!A:B,2,) -> Glossy Protective Cap, 65mm | D4: bronze | E4: СР437 | G4: 40230 | H4: 40230 | I4: 8.5 | J4: 9 | K4: 8 | L4: =(60/I4)*K4 -> 56.470588 | M4: 15 | N4: =15 -> 15 | Q4: =255+485 -> 740 | R4: 6.6 | S4: =R4/(G4*J4/1000) -> 0.018228519 | T4: =(H4/(L4*(Q4-N4-M4-O4)))*((Q4-N4-M4-O4)/(Q4-N4-O4)) -> 0.98262931 | U4: =(H4*J4/(H4*J4+R4*1000)) -> 0.98209781 | V4: =T4*U4 -> 0.96503809 | AC4: =15 -> 15
B5: з65г | C5: =VLOOKUP(B5,Setup!A:B,2,) -> Glossy Protective Cap, 65mm | D5: beige | E5: СР406 | G5: 18000 | H5: 18000 | I5: 8.5 | J5: 9 | K5: 8 | L5: =(60/I5)*K5 -> 56.470588 | M5: 15 | N5: 15 | Q5: =235+105 -> 340 | R5: =9.1+0.3 -> 9.4 | S5: =R5/(G5*J5/1000) -> 0.058024691 | T5: =(H5/(L5*(Q5-N5-M5-O5)))*((Q5-N5-M5-O5)/(Q5-N5-O5)) -> 0.98076923 | U5: =(H5*J5/(H5*J5+R5*1000)) -> 0.94515753 | V5: =T5*U5 -> 0.92698142 | AC5: =10 -> 10
B6: з65г | C6: =VLOOKUP(B6,Setup!A:B,2,) -> Glossy Protective Cap, 65mm | D6: olive | E6: CP436 | G6: 16740 | H6: 16740 | I6: 8.5 | J6: 9 | K6: 8 | L6: =(60/I6)*K6 -> 56.470588 | M6: 10 | Q6: =300 -> 300 | R6: =5.3 -> 5.3 | S6: =R6/(G6*J6/1000) -> 0.035178548 | T6: =(H6/(L6*(Q6-N6-M6-O6)))*((Q6-N6-M6-O6)/(Q6-N6-O6)) -> 0.988125 | U6: =(H6*J6/(H6*J6+R6*1000)) -> 0.96601693 | V6: =T6*U6 -> 0.95454548
B7: з65г | C7: =VLOOKUP(B7,Setup!A:B,2,) -> Glossy Protective Cap, 65mm | D7: blue | E7: СР528 | G7: 10800 | H7: 10800 | I7: 8.5 | J7: 9 | K7: 8 | L7: =(60/I7)*K7 -> 56.470588 | M7: 10 | Q7: =210 -> 210 | R7: 6.3 | S7: =R7/(G7*J7/1000) -> 0.064814815 | T7: =(H7/(L7*(Q7-N7-M7-O7)))*((Q7-N7-M7-O7)/(Q7-N7-O7)) -> 0.91071429 | U7: =(H7*J7/(H7*J7+R7*1000)) -> 0.93913043 | V7: =T7*U7 -> 0.8552795
B8: з65г | C8: =VLOOKUP(B8,Setup!A:B,2,) -> Glossy Protective Cap, 65mm | D8: dark blue | E8: СР405 | G8: 30240 | H8: 30240 | I8: 8.5 | J8: 9 | K8: 8 | L8: =(60/I8)*K8 -> 56.470588 | M8: 10 | N8: =15 -> 15 | Q8: =75+515 -> 590 | R8: =4.4+1.46+0.9+0.7 -> 7.46 | S8: =R8/(G8*J8/1000) -> 0.027410347 | T8: =(H8/(L8*(Q8-N8-M8-O8)))*((Q8-N8-M8-O8)/(Q8-N8-O8)) -> 0.93130435 | U8: =(H8*J8/(H8*J8+R8*1000)) -> 0.97332094 | V8: =T8*U8 -> 0.90645802 | AC8: =25 -> 25
B9: з65г | C9: =VLOOKUP(B9,Setup!A:B,2,) -> Glossy Protective Cap, 65mm | D9: pink | E9: CP435 | G9: 31050 | H9: 31050 | I9: 8.5 | J9: 9 | K9: 8 | L9: =(60/I9)*K9 -> 56.470588 | M9: 25 | N9: 15 | Q9: =190+390 -> 580 | R9: =9.3 -> 9.3 | S9: =R9/(G9*J9/1000) -> 0.033279656 | T9: =(H9/(L9*(Q9-N9-M9-O9)))*((Q9-N9-M9-O9)/(Q9-N9-O9)) -> 0.97317478 | U9: =(H9*J9/(H9*J9+R9*1000)) -> 0.96779221 | V9: =T9*U9 -> 0.94183097 | AC9: 10
B10: з65г | C10: =VLOOKUP(B10,Setup!A:B,2,) -> Glossy Protective Cap, 65mm | D10: pink | E10: СР527 | G10: 10800 | H10: 10800 | I10: 8.5 | J10: 9 | K10: 8 | L10: =(60/I10)*K10 -> 56.470588 | M10: 40 | Q10: =190 -> 190 | R10: =6.8+7+2.2 -> 16 | S10: =R10/(G10*J10/1000) -> 0.16460905 | T10: =(H10/(L10*(Q10-N10-M10-O10)))*((Q10-N10-M10-O10)/(Q10-N10-O10)) -> 1.0065789 | U10: =(H10*J10/(H10*J10+R10*1000)) -> 0.85865724 | V10: =T10*U10 -> 0.8643063
B11: з65г | C11: =VLOOKUP(B11,Setup!A:B,2,) -> Glossy Protective Cap, 65mm | D11: pink-raspberry | E11: СР475 | G11: 40230 | H11: 40230 | I11: 8.5 | J11: 9 | K11: 8 | L11: =(60/I11)*K11 -> 56.470588 | M11: 15 | N11: =15 -> 15 | Q11: =75+655 -> 730 | R11: =7.2+0.9 -> 8.1 | S11: =R11/(G11*J11/1000) -> 0.022371365 | T11: =(H11/(L11*(Q11-N11-M11-O11)))*((Q11-N11-M11-O11)/(Q11-N11-O11)) -> 0.99637238 | U11: =(H11*J11/(H11*J11+R11*1000)) -> 0.97811816 | V11: =T11*U11 -> 0.97456992 | AC11: =15 -> 15
B12: з65г | C12: =VLOOKUP(B12,Setup!A:B,2,) -> Glossy Protective Cap, 65mm | D12: pink | E12: СР442 | G12: 27000 | H12: 27000 | I12: 8.5 | J12: 9 | K12: 8 | L12: =(60/I12)*K12 -> 56.470588 | M12: 20 | N12: 15 | Q12: =35+470 -> 505 | R12: =0.9+5.2 -> 6.1 | S12: =R12/(G12*J12/1000) -> 0.025102881 | T12: =(H12/(L12*(Q12-N12-M12-O12)))*((Q12-N12-M12-O12)/(Q12-N12-O12)) -> 0.97576531 | U12: =(H12*J12/(H12*J12+R12*1000)) -> 0.97551184 | V12: =T12*U12 -> 0.95187061 | AC12: 15
B13: з65г | C13: =VLOOKUP(B13,Setup!A:B,2,) -> Glossy Protective Cap, 65mm | D13: raspberry | E13: СР443 | G13: 27000 | H13: 27000 | I13: 8.5 | J13: 9 | K13: 8 | L13: =(60/I13)*K13 -> 56.470588 | M13: 15 | N13: 15 | Q13: =235+290 -> 525 | R13: =7.8+0.5 -> 8.3 | S13: =R13/(G13*J13/1000) -> 0.034156379 | T13: =(H13/(L13*(Q13-N13-M13-O13)))*((Q13-N13-M13-O13)/(Q13-N13-O13)) -> 0.9375 | U13: =(H13*J13/(H13*J13+R13*1000)) -> 0.96697175 | V13: =T13*U13 -> 0.90653601 | AC13: 15
B14: з65г | C14: =VLOOKUP(B14,Setup!A:B,2,) -> Glossy Protective Cap, 65mm | D14: red-pink | E14: СР455 | G14: 27000 | H14: 27000 | I14: 8.5 | J14: 9 | K14: 8 | L14: =(60/I14)*K14 -> 56.470588 | M14: 25 | N14: 15 | Q14: =405+95 -> 500 | R14: =7.2+3.4 -> 10.6 | S14: =R14/(G14*J14/1000) -> 0.043621399 | T14: =(H14/(L14*(Q14-N14-M14-O14)))*((Q14-N14-M14-O14)/(Q14-N14-O14)) -> 0.98582474 | U14: =(H14*J14/(H14*J14+R14*1000)) -> 0.95820189 | V14: =T14*U14 -> 0.94461913 | AC14: 15
B15: з65г | C15: =VLOOKUP(B15,Setup!A:B,2,) -> Glossy Protective Cap, 65mm | D15: light green | E15: СР533 | G15: 14040 | H15: 14040 | I15: 8.5 | J15: 9 | K15: 8 | L15: =(60/I15)*K15 -> 56.470588 | M15: 20 | Q15: =255 -> 255 | R15: 9 | S15: =R15/(G15*J15/1000) -> 0.071225071 | T15: =(H15/(L15*(Q15-N15-M15-O15)))*((Q15-N15-M15-O15)/(Q15-N15-O15)) -> 0.975 | U15: =(H15*J15/(H15*J15+R15*1000)) -> 0.93351064 | V15: =T15*U15 -> 0.91017287
B16: з65г | C16: =VLOOKUP(B16,Setup!A:B,2,) -> Glossy Protective Cap, 65mm | D16: turquoise | E16: СР451 | G16: 15120 | H16: 15120 | I16: 8.5 | J16: 9 | K16: 8 | L16: =(60/I16)*K16 -> 56.470588 | M16: 15 | Q16: =280 -> 280 | R16: 8.9 | S16: =R16/(G16*J16/1000) -> 0.065402704 | T16: =(H16/(L16*(Q16-N16-M16-O16)))*((Q16-N16-M16-O16)/(Q16-N16-O16)) -> 0.95625 | U16: =(H16*J16/(H16*J16+R16*1000)) -> 0.93861222 | V16: =T16*U16 -> 0.89754794
B17: з65г | C17: =VLOOKUP(B17,Setup!A:B,2,) -> Glossy Protective Cap, 65mm | D17: green | E17: СР444 | G17: 15120 | H17: 15120 | I17: 8.5 | J17: 9 | K17: 8 | L17: =(60/I17)*K17 -> 56.470588 | M17: 15 | N17: 15 | Q17: =40+260 -> 300 | R17: 0.8 | S17: =R17/(G17*J17/1000) -> 0.0058788948 | T17: =(H17/(L17*(Q17-N17-M17-O17)))*((Q17-N17-M17-O17)/(Q17-N17-O17)) -> 0.93947368 | U17: =(H17*J17/(H17*J17+R17*1000)) -> 0.99415546 | V17: =T17*U17 -> 0.9339829 | AC17: 15
B18: з65г | C18: =VLOOKUP(B18,Setup!A:B,2,) -> Glossy Protective Cap, 65mm | D18: bright blue | E18: СР531 | G18: 25110 | H18: 25110 | I18: 8.5 | J18: 9 | K18: 8 | L18: =(60/I18)*K18 -> 56.470588 | M18: 40 | N18: 15 | Q18: =420+40 -> 460 | R18: =8.3+8.6 -> 16.9 | S18: =R18/(G18*J18/1000) -> 0.07478207 | T18: =(H18/(L18*(Q18-N18-M18-O18)))*((Q18-N18-M18-O18)/(Q18-N18-O18)) -> 0.99922753 | U18: =(H18*J18/(H18*J18+R18*1000)) -> 0.93042118 | V18: =T18*U18 -> 0.92970245 | AC18: 15
B19: з65г | C19: =VLOOKUP(B19,Setup!A:B,2,) -> Glossy Protective Cap, 65mm | D19: bronze | E19: СР437 | G19: 60210 | H19: 60210 | I19: 8.5 | J19: 9 | K19: 8 | L19: =(60/I19)*K19 -> 56.470588 | M19: 20 | N19: 15 | Q19: =655+455 -> 1110 | R19: =8.4+0.6 -> 9 | S19: =R19/(G19*J19/1000) -> 0.016608537 | T19: =(H19/(L19*(Q19-N19-M19-O19)))*((Q19-N19-M19-O19)/(Q19-N19-O19)) -> 0.97371575 | U19: =(H19*J19/(H19*J19+R19*1000)) -> 0.9836628 | V19: =T19*U19 -> 0.95780796 | AC19: 10
B20: з65г | C20: =VLOOKUP(B20,Setup!A:B,2,) -> Glossy Protective Cap, 65mm | D20: gold | E20: СР391 | G20: 20250 | H20: 20250 | I20: 8.5 | J20: 9 | K20: 8 | L20: =(60/I20)*K20 -> 56.470588 | M20: 20 | N20: =15 -> 15 | Q20: =245+135 -> 380 | R20: =4.2+0.6 -> 4.8 | S20: =R20/(G20*J20/1000) -> 0.026337449 | T20: =(H20/(L20*(Q20-N20-M20-O20)))*((Q20-N20-M20-O20)/(Q20-N20-O20)) -> 0.98244863 | U20: =(H20*J20/(H20*J20+R20*1000)) -> 0.97433841 | V20: =T20*U20 -> 0.95723744 | AC20: =15 -> 15
B21: з65г | C21: =VLOOKUP(B21,Setup!A:B,2,) -> Glossy Protective Cap, 65mm | D21: pale blue | E21: СР491 | G21: 30240 | H21: 30240 | I21: 8.5 | J21: 9 | K21: 8 | L21: =(60/I21)*K21 -> 56.470588 | M21: 20 | Q21: =565 -> 565 | R21: =8.8 -> 8.8 | S21: =R21/(G21*J21/1000) -> 0.032333921 | T21: =(H21/(L21*(Q21-N21-M21-O21)))*((Q21-N21-M21-O21)/(Q21-N21-O21)) -> 0.94778761 | U21: =(H21*J21/(H21*J21+R21*1000)) -> 0.96867882 | V21: =T21*U21 -> 0.91810178
B22: з65г | C22: =VLOOKUP(B22,Setup!A:B,2,) -> Glossy Protective Cap, 65mm | D22: purple | E22: СР476 | G22: 20250 | H22: 20250 | I22: 8.5 | J22: 9 | K22: 8 | L22: =(60/I22)*K22 -> 56.470588 | M22: 20 | N22: 15 | Q22: =380 -> 380 | R22: =4.58 -> 4.58 | S22: =R22/(G22*J22/1000) -> 0.025130316 | T22: =(H22/(L22*(Q22-N22-M22-O22)))*((Q22-N22-M22-O22)/(Q22-N22-O22)) -> 0.98244863 | U22: =(H22*J22/(H22*J22+R22*1000)) -> 0.97548574 | V22: =T22*U22 -> 0.95836462 | AC22: 10
B23: з65г | C23: =VLOOKUP(B23,Setup!A:B,2,) -> Glossy Protective Cap, 65mm | D23: pink-crimson | E23: СР475 | G23: 30240 | H23: 30240 | I23: 8.5 | J23: 9 | K23: 8 | L23: =(60/I23)*K23 -> 56.470588 | M23: 10 | N23: 15 | Q23: =330+230 -> 560 | R23: =1.66+4.7+0.5 -> 6.86 | S23: =R23/(G23*J23/1000) -> 0.025205761 | T23: =(H23/(L23*(Q23-N23-M23-O23)))*((Q23-N23-M23-O23)/(Q23-N23-O23)) -> 0.98256881 | U23: =(H23*J23/(H23*J23+R23*1000)) -> 0.97541395 | V23: =T23*U23 -> 0.95841132 | AC23: 15
B24: з65г | C24: =VLOOKUP(B24,Setup!A:B,2,) -> Glossy Protective Cap, 65mm | D24: red | E24: СР318 | G24: 20250 | H24: 20250 | I24: 8.5 | J24: 9 | K24: 8 | L24: =(60/I24)*K24 -> 56.470588 | M24: 15 | Q24: =365 -> 365 | R24: =6.7 -> 6.7 | S24: =R24/(G24*J24/1000) -> 0.036762689 | T24: =(H24/(L24*(Q24-N24-M24-O24)))*((Q24-N24-M24-O24)/(Q24-N24-O24)) -> 0.98244863 | U24: =(H24*J24/(H24*J24+R24*1000)) -> 0.96454088 | V24: =T24*U24 -> 0.94761187
B25: з65г | C25: =VLOOKUP(B25,Setup!A:B,2,) -> Glossy Protective Cap, 65mm | D25: green | E25: СР185 | G25: 100170 | H25: 100170 | I25: 8.5 | J25: 9 | K25: 8 | L25: =(60/I25)*K25 -> 56.470588 | M25: 15 | N25: =15+15 -> 30 | Q25: =90+720+720+305 -> 1835 | R25: =7+0.4+0.8 -> 8.2 | S25: =R25/(G25*J25/1000) -> 0.0090956485 | T25: =(H25/(L25*(Q25-N25-M25-O25)))*((Q25-N25-M25-O25)/(Q25-N25-O25)) -> 0.98273892 | U25: =(H25*J25/(H25*J25+R25*1000)) -> 0.99098634 | V25: =T25*U25 -> 0.97388084 | AC25: =10+15 -> 25
B26: з65г | C26: =VLOOKUP(B26,Setup!A:B,2,) -> Glossy Protective Cap, 65mm | D26: bright blue | E26: CP197 | G26: 10260 | H26: 10260 | I26: 8.5 | J26: 9 | K26: 8 | L26: =(60/I26)*K26 -> 56.470588 | M26: 25 | Q26: =190 -> 190 | R26: 9.9 | S26: =R26/(G26*J26/1000) -> 0.10721248 | T26: =(H26/(L26*(Q26-N26-M26-O26)))*((Q26-N26-M26-O26)/(Q26-N26-O26)) -> 0.95625 | U26: =(H26*J26/(H26*J26+R26*1000)) -> 0.90316901 | V26: =T26*U26 -> 0.86365537
B27: з65г | C27: =VLOOKUP(B27,Setup!A:B,2,) -> Glossy Protective Cap, 65mm | D27: turquoise | E27: СР530 | G27: 45090 | H27: 45090 | I27: 8.5 | J27: 9 | K27: 8 | L27: =(60/I27)*K27 -> 56.470588 | M27: 10 | N27: 15 | Q27: =175+645 -> 820 | R27: =6.3+0.6 -> 6.9 | S27: =R27/(G27*J27/1000) -> 0.017003031 | T27: =(H27/(L27*(Q27-N27-M27-O27)))*((Q27-N27-M27-O27)/(Q27-N27-O27)) -> 0.99188665 | U27: =(H27*J27/(H27*J27+R27*1000)) -> 0.98328124 | V27: =T27*U27 -> 0.97530353 | AC27: 10
B28: з65г | C28: =VLOOKUP(B28,Setup!A:B,2,) -> Glossy Protective Cap, 65mm | D28: orange | E28: СР474 | G28: 10260 | H28: 10260 | I28: 8.5 | J28: 9 | K28: 8 | L28: =(60/I28)*K28 -> 56.470588 | M28: 25 | N28: 15 | Q28: =50+130 -> 180 | R28: =7.12+1.3 -> 8.42 | S28: =R28/(G28*J28/1000) -> 0.091184752 | T28: =(H28/(L28*(Q28-N28-M28-O28)))*((Q28-N28-M28-O28)/(Q28-N28-O28)) -> 1.1011364 | U28: =(H28*J28/(H28*J28+R28*1000)) -> 0.91643509 | V28: =T28*U28 -> 1.00912 | AC28: 15
B29: з65г | C29: =VLOOKUP(B29,Setup!A:B,2,) -> Glossy Protective Cap, 65mm | D29: orange | E29: СР241 | G29: 7020 | H29: 7020 | I29: 8.5 | J29: 9 | K29: 8 | L29: =(60/I29)*K29 -> 56.470588 | M29: 15 | Q29: =125 -> 125 | R29: =7.2+2.4 -> 9.6 | S29: =R29/(G29*J29/1000) -> 0.15194682 | T29: =(H29/(L29*(Q29-N29-M29-O29)))*((Q29-N29-M29-O29)/(Q29-N29-O29)) -> 0.9945 | U29: =(H29*J29/(H29*J29+R29*1000)) -> 0.86809563 | V29: =T29*U29 -> 0.8633211
B30: з65г | C30: =VLOOKUP(B30,Setup!A:B,2,) -> Glossy Protective Cap, 65mm | D30: pink | E30: СР223 | G30: 16200 | H30: 16200 | I30: 8.5 | J30: 9 | K30: 8 | L30: =(60/I30)*K30 -> 56.470588 | M30: 20 | Q30: =290 -> 290 | R30: 8.9 | S30: =R30/(G30*J30/1000) -> 0.061042524 | T30: =(H30/(L30*(Q30-N30-M30-O30)))*((Q30-N30-M30-O30)/(Q30-N30-O30)) -> 0.98922414 | U30: =(H30*J30/(H30*J30+R30*1000)) -> 0.9424693 | V30: =T30*U30 -> 0.93231338
B31: з65г | C31: =VLOOKUP(B31,Setup!A:B,2,) -> Glossy Protective Cap, 65mm | D31: green | E31: СР444 | G31: 30240 | H31: 30240 | I31: 8.5 | J31: 9 | K31: 8 | L31: =(60/I31)*K31 -> 56.470588 | M31: 20 | N31: 15 | Q31: =120+440 -> 560 | R31: =10 -> 10 | S31: =R31/(G31*J31/1000) -> 0.036743092 | T31: =(H31/(L31*(Q31-N31-M31-O31)))*((Q31-N31-M31-O31)/(Q31-N31-O31)) -> 0.98256881 | U31: =(H31*J31/(H31*J31+R31*1000)) -> 0.96455912 | V31: =T31*U31 -> 0.9477457 | AC31: 15
B32: з65г | C32: =VLOOKUP(B32,Setup!A:B,2,) -> Glossy Protective Cap, 65mm | D32: beige | E32: СР406 | G32: 180000 | H32: 180000 | I32: 8.5 | J32: 9 | K32: 8 | L32: =(60/I32)*K32 -> 56.470588 | M32: 15 | N32: =15+15+15+15+15 -> 75 | Q32: =265+720+720+720+705+350+15 -> 3495 | R32: =9.8+3.7+1.2+0.5+0.9+4.8+0.8 -> 21.7 | S32: =R32/(G32*J32/1000) -> 0.013395062 | T32: =(H32/(L32*(Q32-N32-M32-O32)))*((Q32-N32-M32-O32)/(Q32-N32-O32)) -> 0.93201754 | U32: =(H32*J32/(H32*J32+R32*1000)) -> 0.98678199 | V32: =T32*U32 -> 0.91969813 | X32: 015 | Y32: 15 | AB32: замерзший гор.канал | AC32: =15+10+15+15+15 -> 70
B33: з65г | C33: =VLOOKUP(B33,Setup!A:B,2,) -> Glossy Protective Cap, 65mm | D33: bronze | E33: СР437 | G33: 30240 | H33: 30240 | I33: 8.5 | J33: 9 | K33: 8 | L33: =(60/I33)*K33 -> 56.470588 | M33: 15 | N33: 15 | Q33: =340+225 -> 565 | R33: =6.2 -> 6.2 | S33: =R33/(G33*J33/1000) -> 0.022780717 | T33: =(H33/(L33*(Q33-N33-M33-O33)))*((Q33-N33-M33-O33)/(Q33-N33-O33)) -> 0.97363636 | U33: =(H33*J33/(H33*J33+R33*1000)) -> 0.97772668 | V33: =T33*U33 -> 0.95195025 | AC33: 15
B34: з65г | C34: =VLOOKUP(B34,Setup!A:B,2,) -> Glossy Protective Cap, 65mm | D34: yellow | E34: CP434 | G34: 22140 | H34: 22140 | I34: 8.5 | J34: 9 | K34: 8 | L34: =(60/I34)*K34 -> 56.470588 | M34: 25 | Q34: =410 -> 410 | R34: 1.4 | S34: =R34/(G34*J34/1000) -> 0.0070259962 | T34: =(H34/(L34*(Q34-N34-M34-O34)))*((Q34-N34-M34-O34)/(Q34-N34-O34)) -> 0.95625 | U34: =(H34*J34/(H34*J34+R34*1000)) -> 0.99302302 | V34: =T34*U34 -> 0.94957827 | X34: 005 | Y34: 60 | AB34: замена ПФ
B35: з65г | C35: =VLOOKUP(B35,Setup!A:B,2,) -> Glossy Protective Cap, 65mm | D35: bright blue | E35: СР531 | G35: 22950 | H35: 22950 | I35: 8.5 | J35: 9 | K35: 8 | L35: =(60/I35)*K35 -> 56.470588 | M35: 180 | P35: replacement of the mold | Q35: =435+180+45 -> 660 | R35: =9+0.6+0.2 -> 9.8 | S35: =R35/(G35*J35/1000) -> 0.047446139 | T35: =(H35/(L35*(Q35-N35-M35-O35)))*((Q35-N35-M35-O35)/(Q35-N35-O35)) -> 0.61576705 | U35: =(H35*J35/(H35*J35+R35*1000)) -> 0.95470303 | V35: =T35*U35 -> 0.58787466 | X35: 005 | Y35: 120 | Z35: 023 | AA35: 45 | AB35: замена ПФ,рем. ПФ, настр.дозатора,разогрев гор.каналов
B36: з65г | C36: =VLOOKUP(B36,Setup!A:B,2,) -> Glossy Protective Cap, 65mm | D36: olive | E36: CP436 | G36: 17010 | H36: 17010 | I36: 8.5 | J36: 9 | K36: 8 | L36: =(60/I36)*K36 -> 56.470588 | M36: 10 | N36: 15 | Q36: =110+220 -> 330 | R36: =4.3+4.7+1.6+1.7 -> 12.3 | S36: =R36/(G36*J36/1000) -> 0.080344895 | T36: =(H36/(L36*(Q36-N36-M36-O36)))*((Q36-N36-M36-O36)/(Q36-N36-O36)) -> 0.95625 | U36: =(H36*J36/(H36*J36+R36*1000)) -> 0.92563033 | V36: =T36*U36 -> 0.885134 | AC36: 15
