Workbook

Sheet 1
A1: Line | B1: Name | C1: Code | D1: English name | E1: Brand | F1: Nomenclature group | G1: Type of nomenclature | H1: Batch number | I1: Planned production, pcs | J1: Actual production, pcs | K1: Target line productivity rate per minute | L1: Line setup time, min | M1: Time of food stops, min | N1: Time for stops independent of line personnel, min | O1: Description of the reason for stopping column "N" | P1: Total batch production time, min | Q1: Initial defective cans, pcs | R1: Manufacturing defects of cans, pcs | S1: Недостача баллонов, шт. | T1: Излишек баллонов, шт. | U1: Number of cans taken by the laboratory for arbitration storage, pcs | V1: Initial defective cans, % | W1: Manufacturing defects of cans, % | X1: Number of cans taken by the laboratory for arbitration storage, % | Y1: ОЕЕ1 | Z1: ОЕЕ2 | AA1: ОЕЕ | AB1: Comment
A2: A1 | B2: Освежитель воздуха AIR WICK Французская ривьера (Морская волна и легкий бриз) | C2: ER-00012432 | D2: =VLOOKUP(C2,Setup!A:F,3,) -> Air freshener AIR WICK French Riviera Sea wave and Light breeze, 290 ml, new | E2: =VLOOKUP(C2,Setup!A:F,4,) -> AIR WICK | F2: =VLOOKUP(C2,Setup!A:F,5,) -> AIR FRESHENERS | G2: =VLOOKUP(C2,Setup!A:F,6,) -> Air fresheners waterbase RB | H2: OA227 | I2: 46832 | J2: 46872 | K2: 120 | L2: 120 | M2: 0 | P2: 534 | Q2: 6 | R2: 6 | U2: 8 | V2: =Q2/(Q2+J2) -> 0.00012799181 | W2: =R2/(R2+J2) -> 0.00012799181 | X2: =U2/(U2+J2) -> 0.00017064846 | Y2: =(J2/(K2*(P2-M2-N2))) -> 0.73146067 | Z2: =(J2/(J2+R2+S2-T2)) -> 0.99987201 | AA2: =Y2*Z2 -> 0.73136705
A3: A1 | B3: Освежитель воздуха AIR WICK Швейцарские альпы (Утренняя роса и зеленый лес) | C3: ER-00012431 | D3: =VLOOKUP(C3,Setup!A:F,3,) -> Air freshener AIR WICK Swiss Alps Morning Dew and Green Forest, 290 ml, new | E3: =VLOOKUP(C3,Setup!A:F,4,) -> AIR WICK | F3: =VLOOKUP(C3,Setup!A:F,5,) -> AIR FRESHENERS | G3: =VLOOKUP(C3,Setup!A:F,6,) -> Air fresheners waterbase RB | H3: OA228 | I3: 18640 | J3: =18600+408 -> 19008 | K3: 120 | L3: 15 | M3: 0 | P3: =201-10+18 -> 209 | Q3: 3 | R3: 2 | U3: =8+6 -> 14 | V3: =Q3/(Q3+J3) -> 0.00015780338 | W3: =R3/(R3+J3) -> 0.00010520779 | X3: =U3/(U3+J3) -> 0.00073598991 | Y3: =(J3/(K3*(P3-M3-N3))) -> 0.75789474 | Z3: =(J3/(J3+R3+S3-T3)) -> 0.99989479 | AA3: =Y3*Z3 -> 0.757815
A4: A1 | B4: Освежитель воздуха AIR WICK Испанские каникулы (Грейпфрут и цветущий лайм) | C4: ER-00012435 | D4: =VLOOKUP(C4,Setup!A:F,3,) -> Air freshener AIR WICK Spanish holidays Grapefruit and Blooming lime, 290 ml, new | E4: =VLOOKUP(C4,Setup!A:F,4,) -> AIR WICK | F4: =VLOOKUP(C4,Setup!A:F,5,) -> AIR FRESHENERS | G4: =VLOOKUP(C4,Setup!A:F,6,) -> Air fresheners waterbase RB | H4: OA289 | I4: 13608 | J4: 13608 | K4: 120 | L4: 15 | M4: 0 | P4: 161 | Q4: 4 | R4: 3 | U4: =8+6 -> 14 | V4: =Q4/(Q4+J4) -> 0.00029385836 | W4: =R4/(R4+J4) -> 0.00022040996 | X4: =U4/(U4+J4) -> 0.0010277492 | Y4: =(J4/(K4*(P4-M4-N4))) -> 0.70434783 | Z4: =(J4/(J4+R4+S4-T4)) -> 0.99977959 | AA4: =Y4*Z4 -> 0.70419258
A5: A1 | B5: Освежитель воздуха AIR WICK Испанские каникулы (Грейпфрут и цветущий лайм) | C5: ER-00012435 | D5: =VLOOKUP(C5,Setup!A:F,3,) -> Air freshener AIR WICK Spanish holidays Grapefruit and Blooming lime, 290 ml, new | E5: =VLOOKUP(C5,Setup!A:F,4,) -> AIR WICK | F5: =VLOOKUP(C5,Setup!A:F,5,) -> AIR FRESHENERS | G5: =VLOOKUP(C5,Setup!A:F,6,) -> Air fresheners waterbase RB | H5: OA288 | I5: 18480 | J5: 18684 | K5: 120 | L5: 15 | M5: 0 | P5: 174 | Q5: 18 | R5: =11+5 -> 16 | U5: 8 | V5: =Q5/(Q5+J5) -> 0.00096246391 | W5: =R5/(R5+J5) -> 0.00085561497 | X5: =U5/(U5+J5) -> 0.00042799058 | Y5: =(J5/(K5*(P5-M5-N5))) -> 0.89482759 | Z5: =(J5/(J5+R5+S5-T5)) -> 0.99914439 | AA5: =Y5*Z5 -> 0.89406196
A6: A1 | B6: Освежитель воздуха AIR WICK Мальдивские мечты (Тропические цветы и пачули) | C6: ER-00012888 | D6: =VLOOKUP(C6,Setup!A:F,3,) -> Air freshener AIR WICK Maldivian Dreams Tropical flowers and Patchouli, 290 ml, new | E6: =VLOOKUP(C6,Setup!A:F,4,) -> AIR WICK | F6: =VLOOKUP(C6,Setup!A:F,5,) -> AIR FRESHENERS | G6: =VLOOKUP(C6,Setup!A:F,6,) -> Air fresheners waterbase RB | H6: OA289 | I6: 27216 | J6: 27216 | K6: 90 | L6: 30 | M6: 0 | P6: 310 | Q6: 8 | R6: 15 | U6: 8 | V6: =Q6/(Q6+J6) -> 0.00029385836 | W6: =R6/(R6+J6) -> 0.00055084279 | X6: =U6/(U6+J6) -> 0.00029385836 | Y6: =(J6/(K6*(P6-M6-N6))) -> 0.97548387 | Z6: =(J6/(J6+R6+S6-T6)) -> 0.99944916 | AA6: =Y6*Z6 -> 0.97494653
A7: A1 | B7: Освежитель воздуха AIR WICK Мальдивские мечты (Тропические цветы и пачули) SRP | C7: ER-00013064 | D7: =VLOOKUP(C7,Setup!A:F,3,) -> Air freshener AIR WICK Maldivian Dreams Tropical flowers and Patchouli, 290 ml, new | E7: =VLOOKUP(C7,Setup!A:F,4,) -> AIR WICK | F7: =VLOOKUP(C7,Setup!A:F,5,) -> AIR FRESHENERS | G7: =VLOOKUP(C7,Setup!A:F,6,) -> Air fresheners waterbase RB | H7: OA285 | I7: 27720 | J7: =3648+24816 -> 28464 | K7: 120 | L7: 15 | M7: 15 | P7: =72-10+241 -> 303 | Q7: 2 | R7: 15 | U7: =6+2 -> 8 | V7: =Q7/(Q7+J7) -> 7.0259257e-05 | W7: =R7/(R7+J7) -> 0.00052670389 | X7: =U7/(U7+J7) -> 0.0002809778 | Y7: =(J7/(K7*(P7-M7-N7))) -> 0.82361111 | Z7: =(J7/(J7+R7+S7-T7)) -> 0.9994733 | AA7: =Y7*Z7 -> 0.82317731
A8: A1 | B8: Освежитель воздуха AIR WICK Японская весна (Цветущая сакура и бергамот) | C8: ER-00012430 | D8: =VLOOKUP(C8,Setup!A:F,3,) -> Air freshener AIR WICK Japanese Spring Cherry blossoms and Bergamot, 290 ml, new | E8: =VLOOKUP(C8,Setup!A:F,4,) -> AIR WICK | F8: =VLOOKUP(C8,Setup!A:F,5,) -> AIR FRESHENERS | G8: =VLOOKUP(C8,Setup!A:F,6,) -> Air fresheners waterbase RB | H8: OA286 | I8: 11550 | J8: 11532 | K8: 120 | L8: 15 | M8: 0 | P8: 129 | Q8: =2+4 -> 6 | R8: 4 | U8: =6+2 -> 8 | V8: =Q8/(Q8+J8) -> 0.0005200208 | W8: =R8/(R8+J8) -> 0.00034674064 | X8: =U8/(U8+J8) -> 0.0006932409 | Y8: =(J8/(K8*(P8-M8-N8))) -> 0.74496124 | Z8: =(J8/(J8+R8+S8-T8)) -> 0.99965326 | AA8: =Y8*Z8 -> 0.74470293
A9: A1 | B9: Освежитель воздуха AIR WICK Марокканское утро (Листочки мяты и Зелёный чай) | C9: ER-00011334 | D9: =VLOOKUP(C9,Setup!A:F,3,) -> Air freshener AIR WICK Moroccan morning Mint leaves and Green tea, 290 ml, new | E9: =VLOOKUP(C9,Setup!A:F,4,) -> AIR WICK | F9: =VLOOKUP(C9,Setup!A:F,5,) -> AIR FRESHENERS | G9: =VLOOKUP(C9,Setup!A:F,6,) -> Air fresheners waterbase RB | H9: OA229 | I9: 8076 | J9: 8064 | K9: 120 | L9: 15 | M9: 0 | P9: 90 | Q9: =3+8 -> 11 | R9: =3+1 -> 4 | U9: =6+2 -> 8 | V9: =Q9/(Q9+J9) -> 0.0013622291 | W9: =R9/(R9+J9) -> 0.00049578582 | X9: =U9/(U9+J9) -> 0.00099108028 | Y9: =(J9/(K9*(P9-M9-N9))) -> 0.74666667 | Z9: =(J9/(J9+R9+S9-T9)) -> 0.99950421 | AA9: =Y9*Z9 -> 0.74629648
A10: A1 | B10: Освежитель воздуха AIR WICK Freshmatic Нежный шелк и лилия SRP | C10: ER-00012474 | D10: =VLOOKUP(C10,Setup!A:F,3,) -> Air freshener AIR WICK Freshmatic Delicate silk and lily, 250 ml | E10: =VLOOKUP(C10,Setup!A:F,4,) -> AIR WICK | F10: =VLOOKUP(C10,Setup!A:F,5,) -> AIR FRESHENERS | G10: =VLOOKUP(C10,Setup!A:F,6,) -> Air fresheners refill RB | H10: OA230 | I10: 61000 | J10: =7974+44670+10590 -> 63234 | K10: 84 | L10: 120 | M10: =15+60+15 -> 90 | P10: =275-10+735-10+226 -> 1216 | Q10: =7+4 -> 11 | R10: =9+7 -> 16 | U10: =38+2 -> 40 | V10: =Q10/(Q10+J10) -> 0.00017392679 | W10: =R10/(R10+J10) -> 0.00025296443 | X10: =U10/(U10+J10) -> 0.00063217119 | Y10: =(J10/(K10*(P10-M10-N10))) -> 0.66854859 | Z10: =(J10/(J10+R10+S10-T10)) -> 0.99974704 | AA10: =Y10*Z10 -> 0.66837947
A11: A1 | B11: Освежитель воздуха AIR WICK Freshmatic Райский десерт | C11: ER-00012477 | D11: =VLOOKUP(C11,Setup!A:F,3,) -> Air freshener AIR WICK Freshmatic Life Scents series Paradise dessert, 250 ml | E11: =VLOOKUP(C11,Setup!A:F,4,) -> AIR WICK | F11: =VLOOKUP(C11,Setup!A:F,5,) -> AIR FRESHENERS | G11: =VLOOKUP(C11,Setup!A:F,6,) -> Air fresheners refill RB | H11: OA231 | I11: 26820 | J11: 27558 | K11: 84 | L11: 15 | M11: 45 | P11: 447 | Q11: =8 -> 8 | R11: =11 -> 11 | U11: =23 -> 23 | V11: =Q11/(Q11+J11) -> 0.00029021258 | W11: =R11/(R11+J11) -> 0.00039899888 | X11: =U11/(U11+J11) -> 0.0008339074 | Y11: =(J11/(K11*(P11-M11-N11))) -> 0.81609808 | Z11: =(J11/(J11+R11+S11-T11)) -> 0.999601 | AA11: =Y11*Z11 -> 0.81577246
A12: A1 | B12: Освежитель воздуха AROMA VOYAGE Hello Aroma тропический смузи | C12: ER-00011755 | D12: =VLOOKUP(C12,Setup!A:F,3,) -> Air freshener AROMA VOYAGE Hello Aroma Verti , Tropical smoothie, 250 ml | E12: =VLOOKUP(C12,Setup!A:F,4,) -> VERTI | F12: =VLOOKUP(C12,Setup!A:F,5,) -> AIR FRESHENERS | G12: =VLOOKUP(C12,Setup!A:F,6,) -> Air fresheners refill | H12: OA436 | I12: 8500 | J12: =8514+6 -> 8520 | K12: 84 | L12: 60 | M12: 0 | P12: =62-10+219 -> 271 | R12: =7 -> 7 | U12: =6 -> 6 | V12: =Q12/(Q12+J12) -> 0 | W12: =R12/(R12+J12) -> 0.00082092178 | X12: =U12/(U12+J12) -> 0.00070372977 | Y12: =(J12/(K12*(P12-M12-N12))) -> 0.37427517 | Z12: =(J12/(J12+R12+S12-T12)) -> 0.99917908 | AA12: =Y12*Z12 -> 0.37396792
A13: A1 | B13: Освежитель воздуха AROMA VOYAGE Hello Aroma алтайская свежесть | C13: ER-00011757 | D13: =VLOOKUP(C13,Setup!A:F,3,) -> Air freshener AROMA VOYAGE Hello Aroma Verti , Altai freshness, 250 ml | E13: =VLOOKUP(C13,Setup!A:F,4,) -> VERTI | F13: =VLOOKUP(C13,Setup!A:F,5,) -> AIR FRESHENERS | G13: =VLOOKUP(C13,Setup!A:F,6,) -> Air fresheners refill | H13: OA437 | I13: 8500 | J13: 8418 | K13: 84 | L13: 15 | M13: 0 | P13: 124 | Q13: =2 -> 2 | R13: =3 -> 3 | U13: =6 -> 6 | V13: =Q13/(Q13+J13) -> 0.00023752969 | W13: =R13/(R13+J13) -> 0.00035625223 | X13: =U13/(U13+J13) -> 0.00071225071 | Y13: =(J13/(K13*(P13-M13-N13))) -> 0.80817972 | Z13: =(J13/(J13+R13+S13-T13)) -> 0.99964375 | AA13: =Y13*Z13 -> 0.80789181
A14: A1 | B14: Освежитель воздуха AROMA VOYAGE Hello Aroma китайская орхидея | C14: ER-00011758 | D14: =VLOOKUP(C14,Setup!A:F,3,) -> Air freshener AROMA VOYAGE Hello Aroma Verti , Chinese orchid, 250 ml | E14: =VLOOKUP(C14,Setup!A:F,4,) -> VERTI | F14: =VLOOKUP(C14,Setup!A:F,5,) -> AIR FRESHENERS | G14: =VLOOKUP(C14,Setup!A:F,6,) -> Air fresheners refill | H14: OA438 | I14: 8500 | J14: 8584 | K14: 84 | L14: 15 | M14: 0 | P14: 125 | Q14: =1 -> 1 | R14: =3 -> 3 | U14: =6 -> 6 | V14: =Q14/(Q14+J14) -> 0.00011648224 | W14: =R14/(R14+J14) -> 0.00034936532 | X14: =U14/(U14+J14) -> 0.00069848661 | Y14: =(J14/(K14*(P14-M14-N14))) -> 0.81752381 | Z14: =(J14/(J14+R14+S14-T14)) -> 0.99965063 | AA14: =Y14*Z14 -> 0.8172382
A15: A1 | B15: Освежитель воздуха AROMA VOYAGE Hello Aroma карельские ягоды | C15: ER-00011756 | D15: =VLOOKUP(C15,Setup!A:F,3,) -> Air freshener AROMA VOYAGE Hello Aroma Verti , Karelian berries, 250 ml | E15: =VLOOKUP(C15,Setup!A:F,4,) -> VERTI | F15: =VLOOKUP(C15,Setup!A:F,5,) -> AIR FRESHENERS | G15: =VLOOKUP(C15,Setup!A:F,6,) -> Air fresheners refill | H15: OA439 | I15: 8500 | J15: 8664 | K15: 84 | L15: 15 | M15: 0 | P15: 124 | Q15: =5 -> 5 | U15: =6 -> 6 | V15: =Q15/(Q15+J15) -> 0.00057676779 | W15: =R15/(R15+J15) -> 0 | X15: =U15/(U15+J15) -> 0.00069204152 | Y15: =(J15/(K15*(P15-M15-N15))) -> 0.83179724 | Z15: =(J15/(J15+R15+S15-T15)) -> 1 | AA15: =Y15*Z15 -> 0.83179724
A16: A1 | B16: Освежитель воздуха Verti Ветивер и бамбук Gold edition | C16: ER-00012767 | D16: =VLOOKUP(C16,Setup!A:F,3,) -> Air freshener VERTI Vetiver and bamboo, 250 ml | E16: =VLOOKUP(C16,Setup!A:F,4,) -> VERTI | F16: =VLOOKUP(C16,Setup!A:F,5,) -> AIR FRESHENERS | G16: =VLOOKUP(C16,Setup!A:F,6,) -> Air fresheners refill | H16: OA432 | I16: 10000 | J16: =7680+1752+510 -> 9942 | K16: 84 | L16: 15 | M16: 0 | P16: =143-10+10 -> 143 | R16: =4 -> 4 | U16: =6 -> 6 | V16: =Q16/(Q16+J16) -> 0 | W16: =R16/(R16+J16) -> 0.00040217173 | X16: =U16/(U16+J16) -> 0.00060313631 | Y16: =(J16/(K16*(P16-M16-N16))) -> 0.82767233 | Z16: =(J16/(J16+R16+S16-T16)) -> 0.99959783 | AA16: =Y16*Z16 -> 0.82733946
A17: A1 | B17: Освежитель воздуха Verti Морская соль и белое дерево Gold edition | C17: ER-00012769 | D17: =VLOOKUP(C17,Setup!A:F,3,) -> Air freshener VERTI Sea salt and white tree, 250 ml | E17: =VLOOKUP(C17,Setup!A:F,4,) -> VERTI | F17: =VLOOKUP(C17,Setup!A:F,5,) -> AIR FRESHENERS | G17: =VLOOKUP(C17,Setup!A:F,6,) -> Air fresheners refill | H17: OA433 | I17: 10000 | J17: 10044 | K17: 84 | L17: 15 | M17: 0 | P17: 139 | Q17: =2 -> 2 | U17: =6 -> 6 | V17: =Q17/(Q17+J17) -> 0.00019908421 | W17: =R17/(R17+J17) -> 0 | X17: =U17/(U17+J17) -> 0.00059701493 | Y17: =(J17/(K17*(P17-M17-N17))) -> 0.8602261 | Z17: =(J17/(J17+R17+S17-T17)) -> 1 | AA17: =Y17*Z17 -> 0.8602261
A18: A1 | B18: Освежитель воздуха Verti Черный перец и апельсиновый цвет Gold edition | C18: ER-00012770 | D18: =VLOOKUP(C18,Setup!A:F,3,) -> Air freshener VERTI Black pepper and orange blossom, 250 ml | E18: =VLOOKUP(C18,Setup!A:F,4,) -> VERTI | F18: =VLOOKUP(C18,Setup!A:F,5,) -> AIR FRESHENERS | G18: =VLOOKUP(C18,Setup!A:F,6,) -> Air fresheners refill | H18: OA434 | I18: 10000 | J18: 10176 | K18: 84 | L18: 15 | M18: 0 | P18: 154 | R18: =1 -> 1 | U18: =6 -> 6 | V18: =Q18/(Q18+J18) -> 0 | W18: =R18/(R18+J18) -> 9.8260784e-05 | X18: =U18/(U18+J18) -> 0.00058927519 | Y18: =(J18/(K18*(P18-M18-N18))) -> 0.78664193 | Z18: =(J18/(J18+R18+S18-T18)) -> 0.99990174 | AA18: =Y18*Z18 -> 0.78656463
A19: A1 | B19: Освежитель воздуха Verti Магнолия и иланг-иланг Gold edition | C19: ER-00012768 | D19: =VLOOKUP(C19,Setup!A:F,3,) -> Air freshener VERTI Magnolia, 250 ml | E19: =VLOOKUP(C19,Setup!A:F,4,) -> VERTI | F19: =VLOOKUP(C19,Setup!A:F,5,) -> AIR FRESHENERS | G19: =VLOOKUP(C19,Setup!A:F,6,) -> Air fresheners refill | H19: OA435 | I19: 10000 | J19: 10092 | K19: 84 | L19: 15 | M19: 0 | P19: 139 | R19: =3 -> 3 | U19: =6 -> 6 | V19: =Q19/(Q19+J19) -> 0 | W19: =R19/(R19+J19) -> 0.00029717682 | X19: =U19/(U19+J19) -> 0.00059417706 | Y19: =(J19/(K19*(P19-M19-N19))) -> 0.8643371 | Z19: =(J19/(J19+R19+S19-T19)) -> 0.99970282 | AA19: =Y19*Z19 -> 0.86408024
A20: A1 | B20: Освежитель воздуха Нужные вещи Ванильный уют НД | C20: ER-00011580 | D20: =VLOOKUP(C20,Setup!A:F,3,) -> Air freshener NUZHNIE VESHI Vanilla comfort, 300 ml, N | E20: =VLOOKUP(C20,Setup!A:F,4,) -> NUZHNYE VESHI | F20: =VLOOKUP(C20,Setup!A:F,5,) -> AIR FRESHENERS | G20: =VLOOKUP(C20,Setup!A:F,6,) -> Air fresheners waterbase | H20: OA292 | I20: 8954 | J20: 9104 | K20: 120 | L20: 120 | M20: 15 | P20: =240 -> 240 | Q20: =1 -> 1 | R20: =4 -> 4 | U20: =6 -> 6 | V20: =Q20/(Q20+J20) -> 0.00010982976 | W20: =R20/(R20+J20) -> 0.00043917435 | X20: =U20/(U20+J20) -> 0.0006586169 | Y20: =(J20/(K20*(P20-M20-N20))) -> 0.33718519 | Z20: =(J20/(J20+R20+S20-T20)) -> 0.99956083 | AA20: =Y20*Z20 -> 0.3370371
A21: A1 | B21: Освежитель воздуха Нужные вещи Киви-виноград. Антитабак НД | C21: ER-00011581 | D21: =VLOOKUP(C21,Setup!A:F,3,) -> Air freshener NUZHNIE VESHI Kiwi grapes. antitobacco, 300 ml, N | E21: =VLOOKUP(C21,Setup!A:F,4,) -> NUZHNYE VESHI | F21: =VLOOKUP(C21,Setup!A:F,5,) -> AIR FRESHENERS | G21: =VLOOKUP(C21,Setup!A:F,6,) -> Air fresheners waterbase | H21: OA297 | I21: 12866 | J21: =1944+216+10896 -> 13056 | K21: 120 | L21: 15 | M21: 0 | P21: =53-10+98 -> 141 | R21: =1 -> 1 | U21: =6 -> 6 | V21: =Q21/(Q21+J21) -> 0 | W21: =R21/(R21+J21) -> 7.6587271e-05 | X21: =U21/(U21+J21) -> 0.00045934773 | Y21: =(J21/(K21*(P21-M21-N21))) -> 0.77163121 | Z21: =(J21/(J21+R21+S21-T21)) -> 0.99992341 | AA21: =Y21*Z21 -> 0.77157211
A22: A1 | B22: Освежитель воздуха Нужные вещи Лайм и корица НД | C22: ER-00011583 | D22: =VLOOKUP(C22,Setup!A:F,3,) -> Air freshener NUZHNIE VISHI Lime and cinnanmon, 300 ml, N | E22: =VLOOKUP(C22,Setup!A:F,4,) -> NUZHNYE VESHI | F22: =VLOOKUP(C22,Setup!A:F,5,) -> AIR FRESHENERS | G22: =VLOOKUP(C22,Setup!A:F,6,) -> Air fresheners waterbase | H22: OA397 | I22: 9756 | J22: =2360+7580 -> 9940 | K22: 120 | L22: 15 | M22: 0 | P22: 100 | Q22: 3 | R22: 2 | U22: 6 | V22: =Q22/(Q22+J22) -> 0.0003017198 | W22: =R22/(R22+J22) -> 0.00020116677 | X22: =U22/(U22+J22) -> 0.00060325759 | Y22: =(J22/(K22*(P22-M22-N22))) -> 0.82833333 | Z22: =(J22/(J22+R22+S22-T22)) -> 0.99979883 | AA22: =Y22*Z22 -> 0.8281667
A23: A1 | B23: Освежитель воздуха Нужные вещи Королева цветов НД | C23: ER-00011582 | D23: =VLOOKUP(C23,Setup!A:F,3,) -> Air freshener NUZHNIE VESHI Queen of flowers, 300 ml, N | E23: =VLOOKUP(C23,Setup!A:F,4,) -> NUZHNYE VESHI | F23: =VLOOKUP(C23,Setup!A:F,5,) -> AIR FRESHENERS | G23: =VLOOKUP(C23,Setup!A:F,6,) -> Air fresheners waterbase | H23: OA399 | I23: 9832 | J23: =5288+4752+6 -> 10046 | K23: 120 | L23: 30 | M23: 0 | P23: 94 | Q23: 4 | R23: 3 | U23: 6 | V23: =Q23/(Q23+J23) -> 0.00039800995 | W23: =R23/(R23+J23) -> 0.00029853717 | X23: =U23/(U23+J23) -> 0.00059689614 | Y23: =(J23/(K23*(P23-M23-N23))) -> 0.89060284 | Z23: =(J23/(J23+R23+S23-T23)) -> 0.99970146 | AA23: =Y23*Z23 -> 0.89033696
A24: A1 | B24: Освежитель воздуха Нужные вещи Летний дождь НД | C24: ER-00011584 | D24: =VLOOKUP(C24,Setup!A:F,3,) -> Air freshener NUZHNIE VESHI Summer rain, 300 ml, N | E24: =VLOOKUP(C24,Setup!A:F,4,) -> NUZHNYE VESHI | F24: =VLOOKUP(C24,Setup!A:F,5,) -> AIR FRESHENERS | G24: =VLOOKUP(C24,Setup!A:F,6,) -> Air fresheners waterbase | H24: OA398 | I24: 10139 | J24: 10154 | K24: 60 | L24: 15 | M24: 0 | P24: 150 | Q24: 9 | R24: 1 | U24: 6 | V24: =Q24/(Q24+J24) -> 0.00088556529 | W24: =R24/(R24+J24) -> 9.8473658e-05 | X24: =U24/(U24+J24) -> 0.00059055118 | Y24: =(J24/(K24*(P24-M24-N24))) -> 1.1282222 | Z24: =(J24/(J24+R24+S24-T24)) -> 0.99990153 | AA24: =Y24*Z24 -> 1.1281111 | AB24: mix
A25: A1 | B25: Освежитель воздуха Нужные вещи Нежная фрезия НД | C25: ER-00011579 | D25: =VLOOKUP(C25,Setup!A:F,3,) -> Air freshener NUZHNIE VESHI Gentle freesia, 300 ml, N | E25: =VLOOKUP(C25,Setup!A:F,4,) -> NUZHNYE VESHI | F25: =VLOOKUP(C25,Setup!A:F,5,) -> AIR FRESHENERS | G25: =VLOOKUP(C25,Setup!A:F,6,) -> Air fresheners waterbase | H25: OA293 | I25: 13229 | J25: 13532 | K25: 60 | L25: 15 | M25: 0 | P25: 242 | Q25: 6 | R25: 1 | U25: 6 | V25: =Q25/(Q25+J25) -> 0.00044319693 | W25: =R25/(R25+J25) -> 7.3893446e-05 | X25: =U25/(U25+J25) -> 0.00044319693 | Y25: =(J25/(K25*(P25-M25-N25))) -> 0.93195592 | Z25: =(J25/(J25+R25+S25-T25)) -> 0.99992611 | AA25: =Y25*Z25 -> 0.93188706 | AB25: mix
A26: A1 | B26: Освежитель воздуха AIR WICK Испанские каникулы (Грейпфрут и цветущий лайм) | C26: ER-00012435 | D26: =VLOOKUP(C26,Setup!A:F,3,) -> Air freshener AIR WICK Spanish holidays Grapefruit and Blooming lime, 290 ml, new | E26: =VLOOKUP(C26,Setup!A:F,4,) -> AIR WICK | F26: =VLOOKUP(C26,Setup!A:F,5,) -> AIR FRESHENERS | G26: =VLOOKUP(C26,Setup!A:F,6,) -> Air fresheners waterbase RB | H26: OA409 | I26: 13608 | J26: 13608 | K26: 120 | L26: 30 | M26: 0 | P26: =51-10+200 -> 241 | Q26: 8 | R26: =5+4 -> 9 | U26: 8 | V26: =Q26/(Q26+J26) -> 0.00058754407 | W26: =R26/(R26+J26) -> 0.00066093853 | X26: =U26/(U26+J26) -> 0.00058754407 | Y26: =(J26/(K26*(P26-M26-N26))) -> 0.47053942 | Z26: =(J26/(J26+R26+S26-T26)) -> 0.99933906 | AA26: =Y26*Z26 -> 0.47022842
A27: A1 | B27: Освежитель воздуха AIR WICK Испанские каникулы (Грейпфрут и цветущий лайм) | C27: ER-00012435 | D27: =VLOOKUP(C27,Setup!A:F,3,) -> Air freshener AIR WICK Spanish holidays Grapefruit and Blooming lime, 290 ml, new | E27: =VLOOKUP(C27,Setup!A:F,4,) -> AIR WICK | F27: =VLOOKUP(C27,Setup!A:F,5,) -> AIR FRESHENERS | G27: =VLOOKUP(C27,Setup!A:F,6,) -> Air fresheners waterbase RB | H27: OA410 | I27: 18480 | J27: 18672 | K27: 120 | L27: 0 | M27: 0 | P27: 200 | Q27: 12 | R27: 15 | U27: 8 | V27: =Q27/(Q27+J27) -> 0.00064226076 | W27: =R27/(R27+J27) -> 0.00080269706 | X27: =U27/(U27+J27) -> 0.00042826552 | Y27: =(J27/(K27*(P27-M27-N27))) -> 0.778 | Z27: =(J27/(J27+R27+S27-T27)) -> 0.9991973 | AA27: =Y27*Z27 -> 0.7773755
A28: A1 | B28: Освежитель воздуха AIR WICK Мальдивские мечты (Тропические цветы и пачули) | C28: ER-00012888 | D28: =VLOOKUP(C28,Setup!A:F,3,) -> Air freshener AIR WICK Maldivian Dreams Tropical flowers and Patchouli, 290 ml, new | E28: =VLOOKUP(C28,Setup!A:F,4,) -> AIR WICK | F28: =VLOOKUP(C28,Setup!A:F,5,) -> AIR FRESHENERS | G28: =VLOOKUP(C28,Setup!A:F,6,) -> Air fresheners waterbase RB | H28: OA409 | I28: 27216 | J28: =27216+100 -> 27316 | K28: 90 | L28: 30 | M28: 15 | P28: 306 | Q28: 12 | R28: 6 | U28: 8 | V28: =Q28/(Q28+J28) -> 0.00043911007 | W28: =R28/(R28+J28) -> 0.00021960325 | X28: =U28/(U28+J28) -> 0.0002927829 | Y28: =(J28/(K28*(P28-M28-N28))) -> 1.0429935 | Z28: =(J28/(J28+R28+S28-T28)) -> 0.9997804 | AA28: =Y28*Z28 -> 1.0427645
A29: A1 | B29: Освежитель воздуха AIR WICK Мальдивские мечты (Тропические цветы и пачули) SRP | C29: ER-00013064 | D29: =VLOOKUP(C29,Setup!A:F,3,) -> Air freshener AIR WICK Maldivian Dreams Tropical flowers and Patchouli, 290 ml, new | E29: =VLOOKUP(C29,Setup!A:F,4,) -> AIR WICK | F29: =VLOOKUP(C29,Setup!A:F,5,) -> AIR FRESHENERS | G29: =VLOOKUP(C29,Setup!A:F,6,) -> Air fresheners waterbase RB | H29: OA226 | I29: 23100 | J29: 23508 | K29: 120 | L29: 0 | M29: 0 | P29: =29-10+234 -> 253 | Q29: 2 | R29: 2 | U29: 8 | V29: =Q29/(Q29+J29) -> 8.5070183e-05 | W29: =R29/(R29+J29) -> 8.5070183e-05 | X29: =U29/(U29+J29) -> 0.00034019391 | Y29: =(J29/(K29*(P29-M29-N29))) -> 0.7743083 | Z29: =(J29/(J29+R29+S29-T29)) -> 0.99991493 | AA29: =Y29*Z29 -> 0.77424243
A30: A1 | B30: Освежитель воздуха AIR WICK Французская ривьера (Морская волна и легкий бриз) | C30: ER-00012432 | D30: =VLOOKUP(C30,Setup!A:F,3,) -> Air freshener AIR WICK French Riviera Sea wave and Light breeze, 290 ml, new | E30: =VLOOKUP(C30,Setup!A:F,4,) -> AIR WICK | F30: =VLOOKUP(C30,Setup!A:F,5,) -> AIR FRESHENERS | G30: =VLOOKUP(C30,Setup!A:F,6,) -> Air fresheners waterbase RB | H30: OA355 | I30: 25717 | J30: 25668 | K30: 120 | L30: 15 | M30: 0 | P30: 261 | Q30: 22 | R30: =16+5 -> 21 | U30: 8 | V30: =Q30/(Q30+J30) -> 0.00085636434 | W30: =R30/(R30+J30) -> 0.00081747051 | X30: =U30/(U30+J30) -> 0.00031157501 | Y30: =(J30/(K30*(P30-M30-N30))) -> 0.81954023 | Z30: =(J30/(J30+R30+S30-T30)) -> 0.99918253 | AA30: =Y30*Z30 -> 0.81887028
A31: A1 | B31: Освежитель воздуха AIR WICK Швейцарские альпы (Утренняя роса и зеленый лес) | C31: ER-00012431 | D31: =VLOOKUP(C31,Setup!A:F,3,) -> Air freshener AIR WICK Swiss Alps Morning Dew and Green Forest, 290 ml, new | E31: =VLOOKUP(C31,Setup!A:F,4,) -> AIR WICK | F31: =VLOOKUP(C31,Setup!A:F,5,) -> AIR FRESHENERS | G31: =VLOOKUP(C31,Setup!A:F,6,) -> Air fresheners waterbase RB | H31: OA411 | I31: 13229 | J31: 11412 | K31: 120 | L31: 15 | M31: 15 | P31: 138 | Q31: 1 | R31: 6 | U31: 8 | V31: =Q31/(Q31+J31) -> 8.7619381e-05 | W31: =R31/(R31+J31) -> 0.00052548607 | X31: =U31/(U31+J31) -> 0.00070052539 | Y31: =(J31/(K31*(P31-M31-N31))) -> 0.77317073 | Z31: =(J31/(J31+R31+S31-T31)) -> 0.99947451 | AA31: =Y31*Z31 -> 0.77276444
A32: A1 | B32: Освежитель воздуха AIR WICK Байкальская свежесть (Свежий воздух и Нежный ландыш) | C32: ER-00012440 | D32: =VLOOKUP(C32,Setup!A:F,3,) -> Air freshener AIR WICK Baikal freshness Fresh air and Delicate lily of the valley, 290 ml, new | E32: =VLOOKUP(C32,Setup!A:F,4,) -> AIR WICK | F32: =VLOOKUP(C32,Setup!A:F,5,) -> AIR FRESHENERS | G32: =VLOOKUP(C32,Setup!A:F,6,) -> Air fresheners waterbase RB | H32: OA414 | I32: 6930 | J32: 6900 | K32: 120 | L32: 15 | M32: 0 | P32: 75 | Q32: =2+5 -> 7 | R32: 9 | U32: 8 | V32: =Q32/(Q32+J32) -> 0.0010134646 | W32: =R32/(R32+J32) -> 0.0013026487 | X32: =U32/(U32+J32) -> 0.0011580776 | Y32: =(J32/(K32*(P32-M32-N32))) -> 0.76666667 | Z32: =(J32/(J32+R32+S32-T32)) -> 0.99869735 | AA32: =Y32*Z32 -> 0.76566797
A33: A1 | B33: Освежитель воздуха AIR WICK Гавайский Ритм (Киви и Яблоко) | C33: ER-00012436 | D33: =VLOOKUP(C33,Setup!A:F,3,) -> Air freshener AIR WICK Hawaiian Rhythm Kiwi and apple, 290 ml, new | E33: =VLOOKUP(C33,Setup!A:F,4,) -> AIR WICK | F33: =VLOOKUP(C33,Setup!A:F,5,) -> AIR FRESHENERS | G33: =VLOOKUP(C33,Setup!A:F,6,) -> Air fresheners waterbase RB | H33: OA418 | I33: 11550 | J33: 10188 | K33: 120 | L33: 15 | M33: 0 | P33: =17+10-10+110 -> 127 | Q33: 22 | R33: 7 | U33: 8 | V33: =Q33/(Q33+J33) -> 0.0021547502 | W33: =R33/(R33+J33) -> 0.00068661108 | X33: =U33/(U33+J33) -> 0.00078462142 | Y33: =(J33/(K33*(P33-M33-N33))) -> 0.66850394 | Z33: =(J33/(J33+R33+S33-T33)) -> 0.99931339 | AA33: =Y33*Z33 -> 0.66804493
A34: A1 | B34: Освежитель воздуха AIR WICK Алтайские луга (Ромашка и сочная зелень) | C34: ER-00012437 | D34: =VLOOKUP(C34,Setup!A:F,3,) -> Air freshener AIR WICK Altai meadows Chamomile and lush greenery, 290 ml, new | E34: =VLOOKUP(C34,Setup!A:F,4,) -> AIR WICK | F34: =VLOOKUP(C34,Setup!A:F,5,) -> AIR FRESHENERS | G34: =VLOOKUP(C34,Setup!A:F,6,) -> Air fresheners waterbase RB | H34: OA424 | I34: 14446 | J34: 14652 | K34: 120 | L34: 15 | M34: 15 | P34: 195 | Q34: 2 | R34: 2 | U34: 8 | V34: =Q34/(Q34+J34) -> 0.00013648151 | W34: =R34/(R34+J34) -> 0.00013648151 | X34: =U34/(U34+J34) -> 0.00054570259 | Y34: =(J34/(K34*(P34-M34-N34))) -> 0.67833333 | Z34: =(J34/(J34+R34+S34-T34)) -> 0.99986352 | AA34: =Y34*Z34 -> 0.67824075
A35: A1 | B35: Освежитель воздуха AIR WICK Испанские каникулы (Грейпфрут и цветущий лайм) | C35: ER-00012435 | D35: =VLOOKUP(C35,Setup!A:F,3,) -> Air freshener AIR WICK Spanish holidays Grapefruit and Blooming lime, 290 ml, new | E35: =VLOOKUP(C35,Setup!A:F,4,) -> AIR WICK | F35: =VLOOKUP(C35,Setup!A:F,5,) -> AIR FRESHENERS | G35: =VLOOKUP(C35,Setup!A:F,6,) -> Air fresheners waterbase RB | H35: OA557 | I35: 4620 | J35: 4608 | K35: 120 | L35: 15 | M35: 0 | P35: 67 | R35: 4 | U35: 8 | V35: =Q35/(Q35+J35) -> 0 | W35: =R35/(R35+J35) -> 0.00086730269 | X35: =U35/(U35+J35) -> 0.0017331023 | Y35: =(J35/(K35*(P35-M35-N35))) -> 0.57313433 | Z35: =(J35/(J35+R35+S35-T35)) -> 0.9991327 | AA35: =Y35*Z35 -> 0.57263725
A36: A1 | B36: Освежитель воздуха Flower shop Золотой лотос и роза 300 мл | C36: ER-00011973 | D36: =VLOOKUP(C36,Setup!A:F,3,) -> Air freshener FLOWER SHOP Golden lotus and rose, 300 ml | E36: =VLOOKUP(C36,Setup!A:F,4,) -> FLOWER SHOP | F36: =VLOOKUP(C36,Setup!A:F,5,) -> AIR FRESHENERS | G36: =VLOOKUP(C36,Setup!A:F,6,) -> Air fresheners waterbase | H36: OA390 | I36: 8643 | J36: 8592 | K36: 120 | L36: 15 | M36: 0 | P36: 129 | Q36: 12 | U36: 6 | V36: =Q36/(Q36+J36) -> 0.0013947001 | W36: =R36/(R36+J36) -> 0 | X36: =U36/(U36+J36) -> 0.00069783671 | Y36: =(J36/(K36*(P36-M36-N36))) -> 0.55503876 | Z36: =(J36/(J36+R36+S36-T36)) -> 1 | AA36: =Y36*Z36 -> 0.55503876
A37: A1 | B37: Освежитель воздуха Flower shop Морские минералы 300 мл | C37: ER-00012698 | D37: =VLOOKUP(C37,Setup!A:F,3,) -> Air freshener FLOWER SHOP Morse minerals, 300 ml, N | E37: =VLOOKUP(C37,Setup!A:F,4,) -> FLOWER SHOP | F37: =VLOOKUP(C37,Setup!A:F,5,) -> AIR FRESHENERS | G37: =VLOOKUP(C37,Setup!A:F,6,) -> Air fresheners waterbase | H37: OA542 | I37: 9141 | J37: 9144 | K37: 120 | L37: 15 | M37: 0 | P37: 95 | R37: 2 | U37: 6 | V37: =Q37/(Q37+J37) -> 0 | W37: =R37/(R37+J37) -> 0.00021867483 | X37: =U37/(U37+J37) -> 0.0006557377 | Y37: =(J37/(K37*(P37-M37-N37))) -> 0.80210526 | Z37: =(J37/(J37+R37+S37-T37)) -> 0.99978133 | AA37: =Y37*Z37 -> 0.80192986
A38: A1 | B38: Освежитель воздуха Flower shop Яблоко и жасмин 300 мл | C38: ER-00011980 | D38: =VLOOKUP(C38,Setup!A:F,3,) -> Air freshener FLOWER SHOP apple and jasmine, 300 ml, N | E38: =VLOOKUP(C38,Setup!A:F,4,) -> FLOWER SHOP | F38: =VLOOKUP(C38,Setup!A:F,5,) -> AIR FRESHENERS | G38: =VLOOKUP(C38,Setup!A:F,6,) -> Air fresheners waterbase | H38: OA510 | I38: 9900 | J38: 10128 | K38: 120 | L38: 15 | M38: 0 | P38: 105 | Q38: 1 | U38: 6 | V38: =Q38/(Q38+J38) -> 9.8726429e-05 | W38: =R38/(R38+J38) -> 0 | X38: =U38/(U38+J38) -> 0.00059206631 | Y38: =(J38/(K38*(P38-M38-N38))) -> 0.80380952 | Z38: =(J38/(J38+R38+S38-T38)) -> 1 | AA38: =Y38*Z38 -> 0.80380952
A39: A1 | B39: Освежитель воздуха Flower shop Антитабак 300 мл | C39: ER-00012699 | D39: =VLOOKUP(C39,Setup!A:F,3,) -> Air freshener FLOWER SHOP Antitabacco, 300 ml, N | E39: =VLOOKUP(C39,Setup!A:F,4,) -> FLOWER SHOP | F39: =VLOOKUP(C39,Setup!A:F,5,) -> AIR FRESHENERS | G39: =VLOOKUP(C39,Setup!A:F,6,) -> Air fresheners waterbase | H39: OA543 | I39: 4400 | J39: =600+3900 -> 4500 | K39: 120 | L39: 15 | M39: 0 | P39: =19+35 -> 54 | Q39: 1 | U39: 6 | V39: =Q39/(Q39+J39) -> 0.00022217285 | W39: =R39/(R39+J39) -> 0 | X39: =U39/(U39+J39) -> 0.0013315579 | Y39: =(J39/(K39*(P39-M39-N39))) -> 0.69444444 | Z39: =(J39/(J39+R39+S39-T39)) -> 1 | AA39: =Y39*Z39 -> 0.69444444
A40: A1 | B40: Освежитель воздуха Flower shop Лайм и мята 300 мл | C40: ER-00012701 | D40: =VLOOKUP(C40,Setup!A:F,3,) -> Air freshener FLOWER SHOP Lime and mint, 300 ml, | E40: =VLOOKUP(C40,Setup!A:F,4,) -> FLOWER SHOP | F40: =VLOOKUP(C40,Setup!A:F,5,) -> AIR FRESHENERS | G40: =VLOOKUP(C40,Setup!A:F,6,) -> Air fresheners waterbase | H40: OA544 | I40: 5100 | J40: 5112 | K40: 120 | L40: 15 | M40: 0 | P40: =60-10 -> 50 | U40: 6 | V40: =Q40/(Q40+J40) -> 0 | W40: =R40/(R40+J40) -> 0 | X40: =U40/(U40+J40) -> 0.0011723329 | Y40: =(J40/(K40*(P40-M40-N40))) -> 0.852 | Z40: =(J40/(J40+R40+S40-T40)) -> 1 | AA40: =Y40*Z40 -> 0.852
...

Sheet 2
A1: Line | B1: Name | C1: Code | D1: English name | E1: Brand | F1: Nomenclature group | G1: Type of nomenclature | H1: Batch number | I1: Planned production, pcs | J1: Actual production, pcs | K1: Target line productivity rate per minute | L1: Line setup time, min | M1: Time of food stops, min | N1: Time for stops independent of line personnel, min | O1: Description of the reason for stopping column "N" | P1: Total batch production time, min | Q1: Initial defective cans, pcs | R1: Manufacturing defects of cans, pcs | S1: Недостача баллонов, шт. | T1: Излишек баллонов, шт. | U1: Number of cans taken by the laboratory for arbitration storage, pcs | V1: Initial defective cans, % | W1: Manufacturing defects of cans, % | X1: Number of cans taken by the laboratory for arbitration storage, % | Y1: ОЕЕ1 | Z1: ОЕЕ2 | AA1: ОЕЕ | AB1: Comment
A2: A2 | B2: Освежитель воздуха Flower shop Нежная фрезия и персик 300 мл | C2: ER-00011974 | D2: =VLOOKUP(C2,Setup!A:F,3,) -> Air freshener FLOWER SHOP Delicate freesia and peach, 300 ml | E2: =VLOOKUP(C2,Setup!A:F,4,) -> FLOWER SHOP | F2: =VLOOKUP(C2,Setup!A:F,5,) -> AIR FRESHENERS | G2: =VLOOKUP(C2,Setup!A:F,6,) -> Air fresheners waterbase | H2: OA209 | I2: 11550 | J2: 11784 | K2: 150 | L2: 120 | M2: 0 | P2: 182 | Q2: 8 | R2: 4 | U2: 6 | V2: =Q2/(Q2+J2) -> 0.00067842605 | W2: =R2/(R2+J2) -> 0.00033932813 | X2: =U2/(U2+J2) -> 0.00050890585 | Y2: =(J2/(K2*(P2-M2-N2))) -> 0.43164835 | Z2: =(J2/(J2+R2+S2-T2)) -> 0.99966067 | AA2: =Y2*Z2 -> 0.43150188
A3: A2 | B3: Освежитель воздуха Альпен Весенний сад 300 мл | C3: ER-00012716 | D3: =VLOOKUP(C3,Setup!A:F,3,) -> Air freshener ALPEN Spring forest, 300 ml | E3: =VLOOKUP(C3,Setup!A:F,4,) -> ALPEN | F3: =VLOOKUP(C3,Setup!A:F,5,) -> AIR FRESHENERS | G3: =VLOOKUP(C3,Setup!A:F,6,) -> Air fresheners waterbase | H3: OA377 | I3: 8784 | J3: 8772 | K3: 150 | L3: 15 | M3: 0 | P3: 78 | Q3: 2 | U3: 6 | V3: =Q3/(Q3+J3) -> 0.0002279462 | W3: =R3/(R3+J3) -> 0 | X3: =U3/(U3+J3) -> 0.000683527 | Y3: =(J3/(K3*(P3-M3-N3))) -> 0.74974359 | Z3: =(J3/(J3+R3+S3-T3)) -> 1 | AA3: =Y3*Z3 -> 0.74974359
A4: A2 | B4: Освежитель воздуха Альпен Нежность хлопка 300 мл | C4: ER-00012495 | D4: =VLOOKUP(C4,Setup!A:F,3,) -> Air freshener AIR PURE BY ALPEN Cotton softness, 300 ml | E4: =VLOOKUP(C4,Setup!A:F,4,) -> ALPEN | F4: =VLOOKUP(C4,Setup!A:F,5,) -> AIR FRESHENERS | G4: =VLOOKUP(C4,Setup!A:F,6,) -> Air fresheners waterbase | H4: OA378 | I4: 10980 | J4: 10968 | K4: 150 | L4: 15 | M4: 0 | P4: 105 | Q4: 2 | U4: 6 | V4: =Q4/(Q4+J4) -> 0.00018231541 | W4: =R4/(R4+J4) -> 0 | X4: =U4/(U4+J4) -> 0.00054674686 | Y4: =(J4/(K4*(P4-M4-N4))) -> 0.69638095 | Z4: =(J4/(J4+R4+S4-T4)) -> 1 | AA4: =Y4*Z4 -> 0.69638095
A5: A2 | B5: Освежитель воздуха Альпен Ландыш и жасмин 300 мл | C5: ER-00012496 | D5: =VLOOKUP(C5,Setup!A:F,3,) -> Air freshener AIR PURE BY ALPEN Lily of the valley and jasmine, 300 ml | E5: =VLOOKUP(C5,Setup!A:F,4,) -> ALPEN | F5: =VLOOKUP(C5,Setup!A:F,5,) -> AIR FRESHENERS | G5: =VLOOKUP(C5,Setup!A:F,6,) -> Air fresheners waterbase | H5: OA379 | I5: 10614 | J5: 10608 | K5: 150 | L5: 15 | M5: 0 | P5: =25-10+76 -> 91 | Q5: 1 | R5: 2 | U5: 6 | V5: =Q5/(Q5+J5) -> 9.4259591e-05 | W5: =R5/(R5+J5) -> 0.00018850141 | X5: =U5/(U5+J5) -> 0.00056529112 | Y5: =(J5/(K5*(P5-M5-N5))) -> 0.77714286 | Z5: =(J5/(J5+R5+S5-T5)) -> 0.9998115 | AA5: =Y5*Z5 -> 0.77699636
A6: A2 | B6: Освежитель воздуха Альпен Антитабак 300 мл | C6: ER-00012707 | D6: =VLOOKUP(C6,Setup!A:F,3,) -> Air freshener ALPEN Antitabacco, 300 ml | E6: =VLOOKUP(C6,Setup!A:F,4,) -> ALPEN | F6: =VLOOKUP(C6,Setup!A:F,5,) -> AIR FRESHENERS | G6: =VLOOKUP(C6,Setup!A:F,6,) -> Air fresheners waterbase | H6: OA191 | I6: 17202 | J6: 17364 | K6: 150 | L6: 15 | M6: 0 | P6: 152 | Q6: 2 | R6: 3 | U6: 6 | V6: =Q6/(Q6+J6) -> 0.00011516757 | W6: =R6/(R6+J6) -> 0.00017274141 | X6: =U6/(U6+J6) -> 0.00034542314 | Y6: =(J6/(K6*(P6-M6-N6))) -> 0.76157895 | Z6: =(J6/(J6+R6+S6-T6)) -> 0.99982726 | AA6: =Y6*Z6 -> 0.76144739
A7: A2 | B7: Освежитель воздуха Альпен Цветок магнолии 300 мл | C7: ER-00012715 | D7: =VLOOKUP(C7,Setup!A:F,3,) -> Air freshener ALPEN Magnolia flower, 300 ml | E7: =VLOOKUP(C7,Setup!A:F,4,) -> ALPEN | F7: =VLOOKUP(C7,Setup!A:F,5,) -> AIR FRESHENERS | G7: =VLOOKUP(C7,Setup!A:F,6,) -> Air fresheners waterbase | H7: OA160 | I7: 19764 | J7: 19764 | K7: 150 | L7: 15 | M7: 0 | P7: 159 | Q7: 2 | R7: 3 | U7: 6 | V7: =Q7/(Q7+J7) -> 0.00010118385 | W7: =R7/(R7+J7) -> 0.0001517681 | X7: =U7/(U7+J7) -> 0.00030349014 | Y7: =(J7/(K7*(P7-M7-N7))) -> 0.82867925 | Z7: =(J7/(J7+R7+S7-T7)) -> 0.99984823 | AA7: =Y7*Z7 -> 0.82855348
A8: A2 | B8: Освежитель воздуха Альпен Утренняя роса 300 мл | C8: ER-00012713 | D8: =VLOOKUP(C8,Setup!A:F,3,) -> Air freshener ALPEN Morning dew, 300 ml | E8: =VLOOKUP(C8,Setup!A:F,4,) -> ALPEN | F8: =VLOOKUP(C8,Setup!A:F,5,) -> AIR FRESHENERS | G8: =VLOOKUP(C8,Setup!A:F,6,) -> Air fresheners waterbase | H8: OA153 | I8: 17568 | J8: 17568 | K8: 150 | L8: 15 | M8: 0 | P8: 157 | Q8: 3 | R8: 2 | U8: 6 | V8: =Q8/(Q8+J8) -> 0.00017073587 | W8: =R8/(R8+J8) -> 0.00011383039 | X8: =U8/(U8+J8) -> 0.00034141345 | Y8: =(J8/(K8*(P8-M8-N8))) -> 0.74598726 | Z8: =(J8/(J8+R8+S8-T8)) -> 0.99988617 | AA8: =Y8*Z8 -> 0.74590235
A9: A2 | B9: Освежитель воздуха Прованс Солнечный апельсин 300 мл GG | C9: ER-00013382 | D9: =VLOOKUP(C9,Setup!A:F,3,) -> Air freshener GREEN COLLECTION BY PROVENCE Sunny Orange, 300 ml, N, Gatter group | E9: =VLOOKUP(C9,Setup!A:F,4,) -> GREEN COLLECTION BY PROVENCE | F9: =VLOOKUP(C9,Setup!A:F,5,) -> AIR FRESHENERS | G9: =VLOOKUP(C9,Setup!A:F,6,) -> Air fresheners waterbase | H9: OA408 | I9: 2000 | J9: 1585 | K9: 150 | L9: 15 | M9: 0 | P9: 20 | Q9: 1 | R9: 1 | U9: 6 | V9: =Q9/(Q9+J9) -> 0.00063051702 | W9: =R9/(R9+J9) -> 0.00063051702 | X9: =U9/(U9+J9) -> 0.0037712131 | Y9: =(J9/(K9*(P9-M9-N9))) -> 0.52833333 | Z9: =(J9/(J9+R9+S9-T9)) -> 0.99936948 | AA9: =Y9*Z9 -> 0.52800021
A10: A2 | B10: Освежитель воздуха Прованс Солнечный апельсин 300 мл | C10: ER-00011705 | D10: =VLOOKUP(C10,Setup!A:F,3,) -> Air freshener GREEN COLLECTION BY PROVENCE Sunny Orange, 300 ml | E10: =VLOOKUP(C10,Setup!A:F,4,) -> GREEN COLLECTION BY PROVENCE | F10: =VLOOKUP(C10,Setup!A:F,5,) -> AIR FRESHENERS | G10: =VLOOKUP(C10,Setup!A:F,6,) -> Air fresheners waterbase | H10: OA408 | I10: 4000 | J10: 4512 | K10: 150 | L10: 0 | M10: 0 | P10: 61 | V10: =Q10/(Q10+J10) -> 0 | W10: =R10/(R10+J10) -> 0 | X10: =U10/(U10+J10) -> 0 | Y10: =(J10/(K10*(P10-M10-N10))) -> 0.49311475 | Z10: =(J10/(J10+R10+S10-T10)) -> 1 | AA10: =Y10*Z10 -> 0.49311475
A11: A2 | B11: Освежитель воздуха Прованс Сирень и лаванда 300 мл GG | C11: ER-00013380 | D11: =VLOOKUP(C11,Setup!A:F,3,) -> Air freshener GREEN COLLECTION BY PROVENCE Lilac and lavender, 300 ml, Gatter group | E11: =VLOOKUP(C11,Setup!A:F,4,) -> GREEN COLLECTION BY PROVENCE | F11: =VLOOKUP(C11,Setup!A:F,5,) -> AIR FRESHENERS | G11: =VLOOKUP(C11,Setup!A:F,6,) -> Air fresheners waterbase | H11: OA386 | I11: 12400 | J11: =6804+1944+3660 -> 12408 | K11: 150 | L11: 15 | M11: 0 | P11: 120 | Q11: =1+2 -> 3 | R11: =1+1 -> 2 | U11: 6 | V11: =Q11/(Q11+J11) -> 0.00024172105 | W11: =R11/(R11+J11) -> 0.00016116035 | X11: =U11/(U11+J11) -> 0.00048332528 | Y11: =(J11/(K11*(P11-M11-N11))) -> 0.68933333 | Z11: =(J11/(J11+R11+S11-T11)) -> 0.99983884 | AA11: =Y11*Z11 -> 0.68922224
A12: A2 | B12: Освежитель воздуха Прованс Сирень и лаванда 300 мл | C12: ER-00011712 | D12: =VLOOKUP(C12,Setup!A:F,3,) -> Air freshener GREEN COLLECTION BY PROVENCE Lilac and lavender, 300 ml | E12: =VLOOKUP(C12,Setup!A:F,4,) -> GREEN COLLECTION BY PROVENCE | F12: =VLOOKUP(C12,Setup!A:F,5,) -> AIR FRESHENERS | G12: =VLOOKUP(C12,Setup!A:F,6,) -> Air fresheners waterbase | H12: OA386 | I12: 2700 | J12: 3168 | K12: 150 | L12: 0 | M12: 0 | P12: 32 | V12: =Q12/(Q12+J12) -> 0 | W12: =R12/(R12+J12) -> 0 | X12: =U12/(U12+J12) -> 0 | Y12: =(J12/(K12*(P12-M12-N12))) -> 0.66 | Z12: =(J12/(J12+R12+S12-T12)) -> 1 | AA12: =Y12*Z12 -> 0.66
A13: A2 | B13: Дезодорант SS Ice blue мужской | C13: 00-00001753 | D13: =VLOOKUP(C13,Setup!A:F,3,) -> Deodorant SPORT STAR Ice blue man, 175 ml | E13: =VLOOKUP(C13,Setup!A:F,4,) -> SPORT STAR | F13: =VLOOKUP(C13,Setup!A:F,5,) -> BODY CARE | G13: =VLOOKUP(C13,Setup!A:F,6,) -> Deodorant | H13: DA029 | I13: 16000 | J13: 16308 | K13: 150 | L13: 60 | M13: 0 | P13: 196 | Q13: 6 | R13: =6+2 -> 8 | U13: 6 | V13: =Q13/(Q13+J13) -> 0.00036778227 | W13: =R13/(R13+J13) -> 0.00049031625 | X13: =U13/(U13+J13) -> 0.00036778227 | Y13: =(J13/(K13*(P13-M13-N13))) -> 0.55469388 | Z13: =(J13/(J13+R13+S13-T13)) -> 0.99950968 | AA13: =Y13*Z13 -> 0.5544219
A14: A2 | B14: Дезодорант EDISON Golden Amber мужской | C14: ER-00012398 | D14: =VLOOKUP(C14,Setup!A:F,3,) -> Deodorant EDISON Golden Amber for men, 150 ml | E14: =VLOOKUP(C14,Setup!A:F,4,) -> EDISON | F14: =VLOOKUP(C14,Setup!A:F,5,) -> BODY CARE | G14: =VLOOKUP(C14,Setup!A:F,6,) -> Deodorant | H14: DA025 | I14: 12078 | J14: 12132 | K14: 150 | L14: 15 | M14: 0 | N14: 29 | O14: the alcogol meter broke | P14: 132 | Q14: 6 | R14: 2 | U14: 6 | V14: =Q14/(Q14+J14) -> 0.00049431537 | W14: =R14/(R14+J14) -> 0.00016482611 | X14: =U14/(U14+J14) -> 0.00049431537 | Y14: =(J14/(K14*(P14-M14-N14))) -> 0.78524272 | Z14: =(J14/(J14+R14+S14-T14)) -> 0.99983517 | AA14: =Y14*Z14 -> 0.78511329
A15: A2 | B15: Дезодорант EDISON Green Vetiver мужской | C15: ER-00012400 | D15: =VLOOKUP(C15,Setup!A:F,3,) -> Deodorant EDISON Green Vetiver for men, 150 ml | E15: =VLOOKUP(C15,Setup!A:F,4,) -> EDISON | F15: =VLOOKUP(C15,Setup!A:F,5,) -> BODY CARE | G15: =VLOOKUP(C15,Setup!A:F,6,) -> Deodorant | H15: DA026 | I15: 12078 | J15: 12444 | K15: 150 | L15: 15 | M15: 0 | P15: 114 | Q15: 3 | R15: 3 | U15: 6 | V15: =Q15/(Q15+J15) -> 0.00024102193 | W15: =R15/(R15+J15) -> 0.00024102193 | X15: =U15/(U15+J15) -> 0.00048192771 | Y15: =(J15/(K15*(P15-M15-N15))) -> 0.7277193 | Z15: =(J15/(J15+R15+S15-T15)) -> 0.99975898 | AA15: =Y15*Z15 -> 0.7275439
A16: A2 | B16: Дезодорант EDISON Orange Bergamot мужской | C16: ER-00012399 | D16: =VLOOKUP(C16,Setup!A:F,3,) -> Deodorant EDISON Orange Bergamot for men, 150 ml | E16: =VLOOKUP(C16,Setup!A:F,4,) -> EDISON | F16: =VLOOKUP(C16,Setup!A:F,5,) -> BODY CARE | G16: =VLOOKUP(C16,Setup!A:F,6,) -> Deodorant | H16: DA027 | I16: 12078 | J16: 12708 | K16: 150 | L16: 15 | M16: 15 | P16: 127 | Q16: 11 | R16: 3 | U16: 6 | V16: =Q16/(Q16+J16) -> 0.00086484787 | W16: =R16/(R16+J16) -> 0.00023601605 | X16: =U16/(U16+J16) -> 0.00047192072 | Y16: =(J16/(K16*(P16-M16-N16))) -> 0.75642857 | Z16: =(J16/(J16+R16+S16-T16)) -> 0.99976398 | AA16: =Y16*Z16 -> 0.75625004
A17: A2 | B17: Дезодорант EDISON Blue Aqua мужской | C17: ER-00012401 | D17: =VLOOKUP(C17,Setup!A:F,3,) -> Deodorant EDISON Blue Aqua for men, 150 ml | E17: =VLOOKUP(C17,Setup!A:F,4,) -> EDISON | F17: =VLOOKUP(C17,Setup!A:F,5,) -> BODY CARE | G17: =VLOOKUP(C17,Setup!A:F,6,) -> Deodorant | H17: DA028 | I17: 12078 | J17: =9720+276+2376 -> 12372 | K17: 150 | L17: 15 | M17: 0 | P17: =115-10+21 -> 126 | Q17: 5 | R17: =1+17 -> 18 | U17: 6 | V17: =Q17/(Q17+J17) -> 0.00040397512 | W17: =R17/(R17+J17) -> 0.0014527845 | X17: =U17/(U17+J17) -> 0.00048473097 | Y17: =(J17/(K17*(P17-M17-N17))) -> 0.65460317 | Z17: =(J17/(J17+R17+S17-T17)) -> 0.99854722 | AA17: =Y17*Z17 -> 0.65365218
A18: A2 | B18: Лак для волос Professional look Fanfare Экстрасильная фиксация | C18: 00-00010355 | D18: =VLOOKUP(C18,Setup!A:F,3,) -> Hairspray PROFESSIONAL LOOK FANFARE exstrastrong hold, 300 ml | E18: =VLOOKUP(C18,Setup!A:F,4,) -> PROFESSIONAL LOOK FANFARE | F18: =VLOOKUP(C18,Setup!A:F,5,) -> HAIR CARE | G18: =VLOOKUP(C18,Setup!A:F,6,) -> Hairspray | H18: UA024 | I18: 21960 | J18: 21936 | K18: 150 | L18: 30 | M18: 0 | N18: 119 | O18: repackaging of old products | P18: 284 | Q18: 6 | R18: 2 | U18: 6 | V18: =Q18/(Q18+J18) -> 0.00027344818 | W18: =R18/(R18+J18) -> 9.1166013e-05 | X18: =U18/(U18+J18) -> 0.00027344818 | Y18: =(J18/(K18*(P18-M18-N18))) -> 0.88630303 | Z18: =(J18/(J18+R18+S18-T18)) -> 0.99990883 | AA18: =Y18*Z18 -> 0.88622223
A19: A2 | B19: Лак для волос Professional look Fanfare Luxury Уход и фиксация | C19: 00-00008693 | D19: =VLOOKUP(C19,Setup!A:F,3,) -> Hairspray PROFESSIONAL LOOK FANFARE Stroke and fixation, 300 ml | E19: =VLOOKUP(C19,Setup!A:F,4,) -> PROFESSIONAL LOOK FANFARE | F19: =VLOOKUP(C19,Setup!A:F,5,) -> HAIR CARE | G19: =VLOOKUP(C19,Setup!A:F,6,) -> Hairspray | H19: UA025 | I19: 21960 | J19: 21564 | K19: 150 | L19: 15 | M19: 0 | P19: 180 | Q19: 26 | R19: 2 | U19: 6 | V19: =Q19/(Q19+J19) -> 0.0012042612 | W19: =R19/(R19+J19) -> 9.273857e-05 | X19: =U19/(U19+J19) -> 0.00027816412 | Y19: =(J19/(K19*(P19-M19-N19))) -> 0.79866667 | Z19: =(J19/(J19+R19+S19-T19)) -> 0.99990726 | AA19: =Y19*Z19 -> 0.7985926
A20: A2 | B20: Лак для волос Pro fixation сверхсильной фиксации товарного знака DELIVEA | C20: 00-00011257 | D20: =VLOOKUP(C20,Setup!A:F,3,) -> Hairspray DELIVEA superstrong hold, 300 ml | E20: =VLOOKUP(C20,Setup!A:F,4,) -> DELIVEA | F20: =VLOOKUP(C20,Setup!A:F,5,) -> HAIR CARE | G20: =VLOOKUP(C20,Setup!A:F,6,) -> Hairspray | H20: UA031 | I20: 87840 | J20: =25641+61026 -> 86667 | K20: 150 | L20: 15 | M20: =15+45 -> 60 | P20: =240-10+505 -> 735 | Q20: =2+39 -> 41 | R20: =8+12 -> 20 | U20: 6 | V20: =Q20/(Q20+J20) -> 0.00047285141 | W20: =R20/(R20+J20) -> 0.0002307151 | X20: =U20/(U20+J20) -> 6.922571e-05 | Y20: =(J20/(K20*(P20-M20-N20))) -> 0.85597037 | Z20: =(J20/(J20+R20+S20-T20)) -> 0.99976928 | AA20: =Y20*Z20 -> 0.85577289
A21: A2 | B21: Пена для бритья EDISON для всех типов кожи с алоэ вера | C21: 00-00010623 | D21: =VLOOKUP(C21,Setup!A:F,3,) -> Shaving foam EDISON all skin types with aloe vera, 300 ml | E21: =VLOOKUP(C21,Setup!A:F,4,) -> EDISON | F21: =VLOOKUP(C21,Setup!A:F,5,) -> BODY CARE | G21: =VLOOKUP(C21,Setup!A:F,6,) -> Shaving foam | H21: BA028 | I21: 23690 | J21: =13608+1068+9720 -> 24396 | K21: 140 | L21: 60 | M21: =15+15+30 -> 60 | P21: =230-10+80 -> 300 | Q21: =24+9 -> 33 | R21: =3+2 -> 5 | U21: 6 | V21: =Q21/(Q21+J21) -> 0.0013508535 | W21: =R21/(R21+J21) -> 0.00020490963 | X21: =U21/(U21+J21) -> 0.00024588149 | Y21: =(J21/(K21*(P21-M21-N21))) -> 0.72607143 | Z21: =(J21/(J21+R21+S21-T21)) -> 0.99979509 | AA21: =Y21*Z21 -> 0.72592265
A22: A2 | B22: Пена для бритья EDISON для чувствительной с витаминами | C22: 00-00010624 | D22: =VLOOKUP(C22,Setup!A:F,3,) -> Shaving foam EDISON for sensitive skin with vitamins, 300 ml | E22: =VLOOKUP(C22,Setup!A:F,4,) -> EDISON | F22: =VLOOKUP(C22,Setup!A:F,5,) -> BODY CARE | G22: =VLOOKUP(C22,Setup!A:F,6,) -> Shaving foam | H22: BA029 | I22: 24541 | J22: 23616 | K22: 140 | L22: 15 | M22: 0 | P22: 183 | Q22: 6 | R22: 2 | U22: 6 | V22: =Q22/(Q22+J22) -> 0.00025400051 | W22: =R22/(R22+J22) -> 8.4681175e-05 | X22: =U22/(U22+J22) -> 0.00025400051 | Y22: =(J22/(K22*(P22-M22-N22))) -> 0.92177986 | Z22: =(J22/(J22+R22+S22-T22)) -> 0.99991532 | AA22: =Y22*Z22 -> 0.9217018
A23: A2 | B23: Пена для бритья DELIVEA для чувствительной кожи MEN | C23: ER-00011870 | D23: =VLOOKUP(C23,Setup!A:F,3,) -> Shaving foam DELIVEA for sensitive skin man, 300 ml | E23: =VLOOKUP(C23,Setup!A:F,4,) -> DELIVEA | F23: =VLOOKUP(C23,Setup!A:F,5,) -> BODY CARE | G23: =VLOOKUP(C23,Setup!A:F,6,) -> Shaving foam | H23: BA030 | I23: 24782 | J23: =20433+5082 -> 25515 | K23: 140 | L23: 15 | M23: 0 | P23: =215-10+38 -> 243 | Q23: =11+3 -> 14 | R23: =3+1 -> 4 | U23: 6 | V23: =Q23/(Q23+J23) -> 0.00054839594 | W23: =R23/(R23+J23) -> 0.00015674595 | X23: =U23/(U23+J23) -> 0.00023510051 | Y23: =(J23/(K23*(P23-M23-N23))) -> 0.75 | Z23: =(J23/(J23+R23+S23-T23)) -> 0.99984325 | AA23: =Y23*Z23 -> 0.74988244
A24: A2 | B24: Пена для бритья Endeavor для чувствительной кожи СЛИВЕР | C24: ER-00013449 | D24: =VLOOKUP(C24,Setup!A:F,3,) -> Shaving foam ENDEAVOR Sensitive for sensitive skin, 200 ml, Sl | E24: =VLOOKUP(C24,Setup!A:F,4,) -> ENDEAVOR | F24: =VLOOKUP(C24,Setup!A:F,5,) -> BODY CARE | G24: =VLOOKUP(C24,Setup!A:F,6,) -> Shaving foam | H24: BA023 | I24: 15000 | J24: 15084 | K24: 140 | L24: 15 | M24: 0 | P24: 167 | Q24: 20 | R24: 2 | U24: 6 | V24: =Q24/(Q24+J24) -> 0.0013241525 | W24: =R24/(R24+J24) -> 0.00013257325 | X24: =U24/(U24+J24) -> 0.00039761431 | Y24: =(J24/(K24*(P24-M24-N24))) -> 0.64516681 | Z24: =(J24/(J24+R24+S24-T24)) -> 0.99986743 | AA24: =Y24*Z24 -> 0.64508128
A25: A2 | B25: Пена для бритья LA FRESH для чувствительной кожи 52*161 | C25: ER-00011919 | D25: =VLOOKUP(C25,Setup!A:F,3,) -> Shaving foam LA FRESH for sensitive skin, 200 ml | E25: =VLOOKUP(C25,Setup!A:F,4,) -> LA FRESH | F25: =VLOOKUP(C25,Setup!A:F,5,) -> BODY CARE | G25: =VLOOKUP(C25,Setup!A:F,6,) -> Shaving foam | H25: BA037 | I25: 8574 | J25: 8772 | K25: 140 | L25: 15 | M25: 0 | P25: 90 | Q25: 3 | R25: 4 | U25: 6 | V25: =Q25/(Q25+J25) -> 0.00034188034 | W25: =R25/(R25+J25) -> 0.00045578851 | X25: =U25/(U25+J25) -> 0.000683527 | Y25: =(J25/(K25*(P25-M25-N25))) -> 0.69619048 | Z25: =(J25/(J25+R25+S25-T25)) -> 0.99954421 | AA25: =Y25*Z25 -> 0.69587316
A26: A2 | B26: Антистатик VERTI Velon | C26: ER-00013428 | D26: =VLOOKUP(C26,Setup!A:F,3,) -> Antistatic Verti VELON, 200 ml | E26: =VLOOKUP(C26,Setup!A:F,4,) -> VELON | F26: =VLOOKUP(C26,Setup!A:F,5,) -> ANISTATIC | G26: =VLOOKUP(C26,Setup!A:F,6,) -> Antistatic | H26: АА004 | I26: 55000 | J26: 56220 | K26: 150 | L26: 120 | M26: 15 | P26: =567 -> 567 | Q26: 40 | R26: 60 | U26: 6 | V26: =Q26/(Q26+J26) -> 0.00071098471 | W26: =R26/(R26+J26) -> 0.0010660981 | X26: =U26/(U26+J26) -> 0.0001067122 | Y26: =(J26/(K26*(P26-M26-N26))) -> 0.67898551 | Z26: =(J26/(J26+R26+S26-T26)) -> 0.9989339 | AA26: =Y26*Z26 -> 0.67826164
A27: A2 | B27: Дезодорант-антиперспирант для ног LA FRESH, 150 мл 45*150 | C27: 00-00001026 | D27: =VLOOKUP(C27,Setup!A:F,3,) -> Deodorant-antiperspirant for feet LA FRESH, 150 ml | E27: =VLOOKUP(C27,Setup!A:F,4,) -> LA FRESH | F27: =VLOOKUP(C27,Setup!A:F,5,) -> SHOE AND CLOTHING CARE | G27: =VLOOKUP(C27,Setup!A:F,6,) -> Shoe deodorant | H27: DA019 | I27: 10000 | J27: =9816 -> 9816 | K27: 150 | L27: 15 | M27: 0 | N27: 385 | O27: repackaging of old products | P27: =345+120 -> 465 | Q27: 10 | R27: 8 | U27: 6 | V27: =Q27/(Q27+J27) -> 0.0010177081 | W27: =R27/(R27+J27) -> 0.00081433225 | X27: =U27/(U27+J27) -> 0.00061087355 | Y27: =(J27/(K27*(P27-M27-N27))) -> 0.818 | Z27: =(J27/(J27+R27+S27-T27)) -> 0.99918567 | AA27: =Y27*Z27 -> 0.81733388
A28: A2 | B28: Мусс для волос PROFESSIONAL TOUCH Pro-vitamin B5 Silk Protein экстрасильной фиксации, 150 мл 45*150 | C28: 00-00001658 | D28: =VLOOKUP(C28,Setup!A:F,3,) -> Hair mousse PROFESSIONAL TOUCH Pro-vitamin B5 Silk Protein extra strong hold, 150 ml | E28: =VLOOKUP(C28,Setup!A:F,4,) -> PROFESSIONAL TOUCH | F28: =VLOOKUP(C28,Setup!A:F,5,) -> HAIR CARE | G28: =VLOOKUP(C28,Setup!A:F,6,) -> Hair mousse | H28: UA023 | I28: 30000 | J28: =13440+1008+15696 -> 30144 | K28: 140 | L28: 30 | M28: 45 | N28: 120 | O28: repackaging of old products | P28: =390-15+160 -> 535 | Q28: =21+4 -> 25 | R28: =7+52 -> 59 | U28: =6+6 -> 12 | V28: =Q28/(Q28+J28) -> 0.00082866519 | W28: =R28/(R28+J28) -> 0.0019534483 | X28: =U28/(U28+J28) -> 0.00039793076 | Y28: =(J28/(K28*(P28-M28-N28))) -> 0.5819305 | Z28: =(J28/(J28+R28+S28-T28)) -> 0.99804655 | AA28: =Y28*Z28 -> 0.58079373
A29: A2 | B29: Мусс для волос PROFESSIONAL TOUCH Pro-Vitamin B5&Collagen сильная фиксация,150 мл 45*150 | C29: ER-00011901 | D29: =VLOOKUP(C29,Setup!A:F,3,) -> Hair mousse PROFESSIONAL TOUCH Pro vitamin B5B5&Collagen strong hold, 150 ml | E29: =VLOOKUP(C29,Setup!A:F,4,) -> PROFESSIONAL TOUCH | F29: =VLOOKUP(C29,Setup!A:F,5,) -> HAIR CARE | G29: =VLOOKUP(C29,Setup!A:F,6,) -> Hair mousse | H29: UA032 | I29: 6500 | J29: 6888 | K29: 140 | L29: 15 | M29: =15+15 -> 30 | P29: 104 | Q29: 1 | R29: 4 | U29: 6 | V29: =Q29/(Q29+J29) -> 0.00014515895 | W29: =R29/(R29+J29) -> 0.00058038305 | X29: =U29/(U29+J29) -> 0.00087032202 | Y29: =(J29/(K29*(P29-M29-N29))) -> 0.66486486 | Z29: =(J29/(J29+R29+S29-T29)) -> 0.99941962 | AA29: =Y29*Z29 -> 0.66447899
A30: A2 | B30: Мусс для волос OLIVIA Пышная грива 4 степень фиксации, 150 мл, trends 45*150 | C30: ER-00012333 | D30: =VLOOKUP(C30,Setup!A:F,3,) -> Hair mousse OLIVIA Lush mane Lush mane trends line, 150 ml | E30: =VLOOKUP(C30,Setup!A:F,4,) -> OLIVIA | F30: =VLOOKUP(C30,Setup!A:F,5,) -> HAIR CARE | G30: =VLOOKUP(C30,Setup!A:F,6,) -> Hair mousse | H30: UA018 | I30: 6500 | J30: 6678 | K30: 140 | L30: 15 | M30: =30+30+40 -> 100 | P30: 156 | Q30: 5 | R30: 12 | U30: 12 | V30: =Q30/(Q30+J30) -> 0.00074816699 | W30: =R30/(R30+J30) -> 0.001793722 | X30: =U30/(U30+J30) -> 0.001793722 | Y30: =(J30/(K30*(P30-M30-N30))) -> 0.85178571 | Z30: =(J30/(J30+R30+S30-T30)) -> 0.99820628 | AA30: =Y30*Z30 -> 0.85025785
A31: A2 | B31: Мусс для волос OLIVIA Мега стойкость и Термо защита cверхсильная фиксация 6, 150 мл, fitocare 45*150 | C31: ER-00012334 | D31: =VLOOKUP(C31,Setup!A:F,3,) -> Hair mousse OLIVIA Mega durability and thermal protection, super strong hold 6, 150 ml, fitocare line | E31: =VLOOKUP(C31,Setup!A:F,4,) -> OLIVIA | F31: =VLOOKUP(C31,Setup!A:F,5,) -> HAIR CARE | G31: =VLOOKUP(C31,Setup!A:F,6,) -> Hair mousse | H31: UA021 | I31: 6500 | J31: 6491 | K31: 140 | L31: 15 | M31: 0 | P31: 84 | R31: 9 | U31: 6 | V31: =Q31/(Q31+J31) -> 0 | W31: =R31/(R31+J31) -> 0.0013846154 | X31: =U31/(U31+J31) -> 0.00092350316 | Y31: =(J31/(K31*(P31-M31-N31))) -> 0.55195578 | Z31: =(J31/(J31+R31+S31-T31)) -> 0.99861538 | AA31: =Y31*Z31 -> 0.55119154
A32: A2 | B32: Мусс для волос OLIVIA Супер объем от корней мегафиксация 5, 150 мл, fitocare 45*150 | C32: ER-00012335 | D32: =VLOOKUP(C32,Setup!A:F,3,) -> Hair mousse OLIVIA Super volume from roots mega fixation 5, 150 ml, fitocare line | E32: =VLOOKUP(C32,Setup!A:F,4,) -> OLIVIA | F32: =VLOOKUP(C32,Setup!A:F,5,) -> HAIR CARE | G32: =VLOOKUP(C32,Setup!A:F,6,) -> Hair mousse | H32: UA022 | I32: 6500 | J32: 6751 | K32: 140 | L32: 15 | M32: 15 | P32: 96 | Q32: 5 | R32: 14 | U32: 6 | V32: =Q32/(Q32+J32) -> 0.00074008289 | W32: =R32/(R32+J32) -> 0.0020694752 | X32: =U32/(U32+J32) -> 0.00088796803 | Y32: =(J32/(K32*(P32-M32-N32))) -> 0.59532628 | Z32: =(J32/(J32+R32+S32-T32)) -> 0.99793052 | AA32: =Y32*Z32 -> 0.59409427
A33: A2 | B33: Мусс для волос OLIVIA Expert PRO Flex&Control, 150 мл 45*150 | C33: ER-00011391 | D33: =VLOOKUP(C33,Setup!A:F,3,) -> Hair mousse OLIVIA Expert Pro Flex and Control, 150 ml | E33: =VLOOKUP(C33,Setup!A:F,4,) -> OLIVIA | F33: =VLOOKUP(C33,Setup!A:F,5,) -> HAIR CARE | G33: =VLOOKUP(C33,Setup!A:F,6,) -> Hair mousse | H33: UA019 | I33: 6500 | J33: =3663+3363 -> 7026 | K33: 140 | L33: 15 | M33: 0 | N33: =45+48 -> 93 | O33: repackaging of old products | P33: =135-10+85 -> 210 | Q33: =2+3 -> 5 | R33: =6+32 -> 38 | U33: 12 | V33: =Q33/(Q33+J33) -> 0.0007111364 | W33: =R33/(R33+J33) -> 0.0053793884 | X33: =U33/(U33+J33) -> 0.0017050298 | Y33: =(J33/(K33*(P33-M33-N33))) -> 0.42893773 | Z33: =(J33/(J33+R33+S33-T33)) -> 0.99462061 | AA33: =Y33*Z33 -> 0.42663031
A34: A2 | B34: Мусс для волос OLIVIA Expert PRO Volume&power, 150 мл 45*150 | C34: ER-00011392 | D34: =VLOOKUP(C34,Setup!A:F,3,) -> Hair mousse OLIVIA Expert Pro Volume and power, 150 ml | E34: =VLOOKUP(C34,Setup!A:F,4,) -> OLIVIA | F34: =VLOOKUP(C34,Setup!A:F,5,) -> HAIR CARE | G34: =VLOOKUP(C34,Setup!A:F,6,) -> Hair mousse | H34: UA020 | I34: 6500 | J34: 6310 | K34: 140 | L34: 15 | M34: 0 | P34: 120 | Q34: 4 | R34: 16 | U34: 6 | V34: =Q34/(Q34+J34) -> 0.00063351283 | W34: =R34/(R34+J34) -> 0.0025292444 | X34: =U34/(U34+J34) -> 0.00094996833 | Y34: =(J34/(K34*(P34-M34-N34))) -> 0.37559524 | Z34: =(J34/(J34+R34+S34-T34)) -> 0.99747076 | AA34: =Y34*Z34 -> 0.37464527
A35: A2 | B35: Дезодорант SS Ice blue мужской НД | C35: ER-00013566 | D35: =VLOOKUP(C35,Setup!A:F,3,) -> Deodorant SPORT STAR Ice blue for men, 175 ml, F | E35: =VLOOKUP(C35,Setup!A:F,4,) -> SPORT STAR | F35: =VLOOKUP(C35,Setup!A:F,5,) -> BODY CARE | G35: =VLOOKUP(C35,Setup!A:F,6,) -> Deodorant | H35: DA040 | I35: 12000 | J35: 11976 | K35: 150 | L35: 120 | M35: 0 | P35: 342 | Q35: 12 | R35: =12+12+14 -> 38 | U35: 6 | V35: =Q35/(Q35+J35) -> 0.001001001 | W35: =R35/(R35+J35) -> 0.0031629765 | X35: =U35/(U35+J35) -> 0.00050075113 | Y35: =(J35/(K35*(P35-M35-N35))) -> 0.23345029 | Z35: =(J35/(J35+R35+S35-T35)) -> 0.99683702 | AA35: =Y35*Z35 -> 0.23271189
A36: A2 | B36: Дезодорант SS Ice blue мужской | C36: 00-00001753 | D36: =VLOOKUP(C36,Setup!A:F,3,) -> Deodorant SPORT STAR Ice blue man, 175 ml | E36: =VLOOKUP(C36,Setup!A:F,4,) -> SPORT STAR | F36: =VLOOKUP(C36,Setup!A:F,5,) -> BODY CARE | G36: =VLOOKUP(C36,Setup!A:F,6,) -> Deodorant | H36: DA034 | I36: 16305 | J36: 16296 | K36: 150 | L36: 30 | M36: 15 | P36: 167 | Q36: 3 | R36: 1 | U36: 6 | V36: =Q36/(Q36+J36) -> 0.00018406037 | W36: =R36/(R36+J36) -> 6.1360987e-05 | X36: =U36/(U36+J36) -> 0.000368053 | Y36: =(J36/(K36*(P36-M36-N36))) -> 0.71473684 | Z36: =(J36/(J36+R36+S36-T36)) -> 0.99993864 | AA36: =Y36*Z36 -> 0.71469299
A37: A2 | B37: Дезодорант EDISON Golden Amber мужской | C37: ER-00012398 | D37: =VLOOKUP(C37,Setup!A:F,3,) -> Deodorant EDISON Golden Amber for men, 150 ml | E37: =VLOOKUP(C37,Setup!A:F,4,) -> EDISON | F37: =VLOOKUP(C37,Setup!A:F,5,) -> BODY CARE | G37: =VLOOKUP(C37,Setup!A:F,6,) -> Deodorant | H37: DA030 | I37: 12078 | J37: =12000 -> 12000 | K37: 150 | L37: 15 | M37: 0 | P37: =21-10+149 -> 160 | Q37: 2 | R37: 2 | U37: 6 | V37: =Q37/(Q37+J37) -> 0.00016663889 | W37: =R37/(R37+J37) -> 0.00016663889 | X37: =U37/(U37+J37) -> 0.00049975012 | Y37: =(J37/(K37*(P37-M37-N37))) -> 0.5 | Z37: =(J37/(J37+R37+S37-T37)) -> 0.99983336 | AA37: =Y37*Z37 -> 0.49991668
A38: A2 | B38: Дезодорант EDISON Orange Bergamot мужской | C38: ER-00012399 | D38: =VLOOKUP(C38,Setup!A:F,3,) -> Deodorant EDISON Orange Bergamot for men, 150 ml | E38: =VLOOKUP(C38,Setup!A:F,4,) -> EDISON | F38: =VLOOKUP(C38,Setup!A:F,5,) -> BODY CARE | G38: =VLOOKUP(C38,Setup!A:F,6,) -> Deodorant | H38: DA032 | I38: 12078 | J38: 12120 | K38: 150 | L38: 15 | M38: 15 | P38: 121 | Q38: 1 | R38: 2 | U38: 6 | V38: =Q38/(Q38+J38) -> 8.2501444e-05 | W38: =R38/(R38+J38) -> 0.00016498928 | X38: =U38/(U38+J38) -> 0.00049480455 | Y38: =(J38/(K38*(P38-M38-N38))) -> 0.76226415 | Z38: =(J38/(J38+R38+S38-T38)) -> 0.99983501 | AA38: =Y38*Z38 -> 0.76213839
A39: A2 | B39: Дезодорант EDISON Green Vetiver мужской | C39: ER-00012400 | D39: =VLOOKUP(C39,Setup!A:F,3,) -> Deodorant EDISON Green Vetiver for men, 150 ml | E39: =VLOOKUP(C39,Setup!A:F,4,) -> EDISON | F39: =VLOOKUP(C39,Setup!A:F,5,) -> BODY CARE | G39: =VLOOKUP(C39,Setup!A:F,6,) -> Deodorant | H39: DA031 | I39: 12078 | J39: 11988 | K39: 150 | L39: 15 | M39: 0 | P39: 94 | Q39: 2 | R39: 5 | U39: 6 | V39: =Q39/(Q39+J39) -> 0.00016680567 | W39: =R39/(R39+J39) -> 0.00041690986 | X39: =U39/(U39+J39) -> 0.00050025013 | Y39: =(J39/(K39*(P39-M39-N39))) -> 0.85021277 | Z39: =(J39/(J39+R39+S39-T39)) -> 0.99958309 | AA39: =Y39*Z39 -> 0.8498583
A40: A2 | B40: Дезодорант EDISON Blue Aqua мужской | C40: ER-00012401 | D40: =VLOOKUP(C40,Setup!A:F,3,) -> Deodorant EDISON Blue Aqua for men, 150 ml | E40: =VLOOKUP(C40,Setup!A:F,4,) -> EDISON | F40: =VLOOKUP(C40,Setup!A:F,5,) -> BODY CARE | G40: =VLOOKUP(C40,Setup!A:F,6,) -> Deodorant | H40: DA033 | I40: 12078 | J40: 12024 | K40: 150 | L40: 15 | M40: 0 | P40: 104 | Q40: 2 | R40: 2 | U40: 6 | V40: =Q40/(Q40+J40) -> 0.00016630634 | W40: =R40/(R40+J40) -> 0.00016630634 | X40: =U40/(U40+J40) -> 0.00049875312 | Y40: =(J40/(K40*(P40-M40-N40))) -> 0.77076923 | Z40: =(J40/(J40+R40+S40-T40)) -> 0.99983369 | AA40: =Y40*Z40 -> 0.77064105
...

Sheet 3
A1: Line | B1: Name | C1: Code | D1: English name | E1: Brand | F1: Nomenclature group | G1: Type of nomenclature | H1: Batch number | I1: Planned production, pcs | J1: Actual production, pcs | K1: Target line productivity rate per minute | L1: Line setup time, min | M1: Time of food stops, min | N1: Time for stops independent of line personnel, min | O1: Description of the reason for stopping column "N" | P1: Total batch production time, min | Q1: Initial defective cans, pcs | R1: Manufacturing defects of cans, pcs | S1: Недостача баллонов, шт. | T1: Излишек баллонов, шт. | U1: Number of cans taken by the laboratory for arbitration storage, pcs | V1: Initial defective cans, % | W1: Manufacturing defects of cans, % | X1: Number of cans taken by the laboratory for arbitration storage, % | Y1: ОЕЕ1 | Z1: ОЕЕ2 | AA1: ОЕЕ | AB1: Comment
A2: А3 | B2: Освежитель воздуха Либерхаус Тропический остров | C2: 00-00001703 | D2: =VLOOKUP(C2,Setup!A:F,3,) -> Air freshener LIBERHAUS Tropical island, 250 ml | E2: =VLOOKUP(C2,Setup!A:F,4,) -> LIBERHAUS | F2: =VLOOKUP(C2,Setup!A:F,5,) -> AIR FRESHENERS | G2: =VLOOKUP(C2,Setup!A:F,6,) -> Air fresheners refill | H2: OA348 | I2: 35360 | J2: =15312+20040 -> 35352 | K2: 84 | L2: 15 | M2: 0 | P2: =229+275 -> 504 | Q2: =2+1 -> 3 | U2: 6 | V2: =Q2/(Q2+J2) -> 8.4853627e-05 | W2: =R2/(R2+J2) -> 0 | X2: =U2/(U2+J2) -> 0.00016969286 | Y2: =(J2/(K2*(P2-M2-N2))) -> 0.83503401 | Z2: =(J2/(J2+R2+S2-T2)) -> 1 | AA2: =Y2*Z2 -> 0.83503401
A3: А3 | B3: Освежитель воздуха Прованс Фруктовый десерт 250 мл | C3: ER-00012049 | D3: =VLOOKUP(C3,Setup!A:F,3,) -> Air freshener GREEN COLLECTION BY PROVENCE Fruit dessert, 250 ml | E3: =VLOOKUP(C3,Setup!A:F,4,) -> GREEN COLLECTION BY PROVENCE | F3: =VLOOKUP(C3,Setup!A:F,5,) -> AIR FRESHENERS | G3: =VLOOKUP(C3,Setup!A:F,6,) -> Air fresheners refill | H3: OA211 | I3: 4200 | J3: 4224 | K3: 84 | L3: 15 | M3: 0 | P3: 65 | Q3: 4 | R3: 5 | U3: 4 | V3: =Q3/(Q3+J3) -> 0.00094607379 | W3: =R3/(R3+J3) -> 0.0011823126 | X3: =U3/(U3+J3) -> 0.00094607379 | Y3: =(J3/(K3*(P3-M3-N3))) -> 0.77362637 | Z3: =(J3/(J3+R3+S3-T3)) -> 0.99881769 | AA3: =Y3*Z3 -> 0.77271171
A4: А3 | B4: Освежитель воздуха Прованс Райское наслаждение 250 мл | C4: ER-00012048 | D4: =VLOOKUP(C4,Setup!A:F,3,) -> Air freshener GREEN COLLECTION BY PROVENCEParadise pleasure, 250 ml | E4: =VLOOKUP(C4,Setup!A:F,4,) -> GREEN COLLECTION BY PROVENCE | F4: =VLOOKUP(C4,Setup!A:F,5,) -> AIR FRESHENERS | G4: =VLOOKUP(C4,Setup!A:F,6,) -> Air fresheners refill | H4: OA364 | I4: 6000 | J4: 6108 | K4: 84 | L4: 15 | M4: 0 | P4: 96 | Q4: 3 | R4: 1 | U4: 6 | V4: =Q4/(Q4+J4) -> 0.00049091802 | W4: =R4/(R4+J4) -> 0.00016369291 | X4: =U4/(U4+J4) -> 0.00098135427 | Y4: =(J4/(K4*(P4-M4-N4))) -> 0.75744048 | Z4: =(J4/(J4+R4+S4-T4)) -> 0.99983631 | AA4: =Y4*Z4 -> 0.75731649
A5: А3 | B5: Освежитель воздуха Прованс Бодрящий лайм 250 мл GG | C5: ER-00013392 | D5: =VLOOKUP(C5,Setup!A:F,3,) -> Air freshener GREEN COLLECTION BY PROVENCE Invigorating Lime, 250 ml, Gatter group | E5: =VLOOKUP(C5,Setup!A:F,4,) -> GREEN COLLECTION BY PROVENCE | F5: =VLOOKUP(C5,Setup!A:F,5,) -> AIR FRESHENERS | G5: =VLOOKUP(C5,Setup!A:F,6,) -> Air fresheners refill | H5: OA188 | I5: 1000 | J5: 1008 | K5: 84 | L5: 15 | M5: 0 | P5: 20 | Q5: 19 | U5: 4 | V5: =Q5/(Q5+J5) -> 0.018500487 | W5: =R5/(R5+J5) -> 0 | X5: =U5/(U5+J5) -> 0.0039525692 | Y5: =(J5/(K5*(P5-M5-N5))) -> 0.6 | Z5: =(J5/(J5+R5+S5-T5)) -> 1 | AA5: =Y5*Z5 -> 0.6
A6: А3 | B6: Освежитель воздуха Прованс Бодрящий лайм 250 мл | C6: ER-00012044 | D6: =VLOOKUP(C6,Setup!A:F,3,) -> Air freshener GREEN COLLECTION BY PROVENCE Invigorating Lime, 250 ml | E6: =VLOOKUP(C6,Setup!A:F,4,) -> GREEN COLLECTION BY PROVENCE | F6: =VLOOKUP(C6,Setup!A:F,5,) -> AIR FRESHENERS | G6: =VLOOKUP(C6,Setup!A:F,6,) -> Air fresheners refill | H6: OA188 | I6: 2200 | J6: 2244 | K6: 84 | L6: 0 | M6: 0 | P6: 40 | V6: =Q6/(Q6+J6) -> 0 | W6: =R6/(R6+J6) -> 0 | X6: =U6/(U6+J6) -> 0 | Y6: =(J6/(K6*(P6-M6-N6))) -> 0.66785714 | Z6: =(J6/(J6+R6+S6-T6)) -> 1 | AA6: =Y6*Z6 -> 0.66785714
